Workbook

Sheet README
A1: MU comparable companies workbook — contents and status
A3: Sheet | B3: Contents | C3: Status
A4: Market Data | B4: EV bridge. Prices USD as of 15 Sep 2026 (LSEG converted). Local-currency entries retained in cols O/P. | C4: COMPLETE
A5: Financial Data | B5: LTM fundamentals USD + growth/profitability benchmarks. | C5: COMPLETE
A6: Valuation Multiples | B6: LTM multiples from Market Data and Financial Data. NTM suppressed. | C6: LTM COMPLETE
A7: Implied Valuation | B7: Implied EV → equity → per share on peer LTM EV/EBITDA. Peer tiers, betas, fiscal year ends. | C7: COMPLETE (LTM)
A8: Current Comps (USD) | B8: Hard-coded current multiples and the sector return comparison. The version used in §5.7. | C8: COMPLETE
A9: Peer Benchmark (S4) | B9: Operating and balance-sheet benchmarks. Needs no prices. Used in §4. | C9: COMPLETE
A10: Normalized & P-B vs ROE | B10: MU 7-yr multiple history, P/B vs ROE, and the forward-book reconciliation. | C10: COMPLETE
A11: WACC Build | B11: Constructed WACC 14.1% on Blume beta 1.84. Sensitivity by beta treatment. | C11: COMPLETE
A13: Companion file: MU_DCF_Model.xlsx — scenario DCF, reverse DCF, sensitivity. Verified to reconcile with the notebook.

Sheet Market Data
A1: Micron Technology, Inc. (NASDAQ: MU)
A2: Trading Comparable Companies Analysis
A3: Market data as of 15 September 2026. ALL PRICES IN USD.
A4: Peer prices are LSEG’s own USD-converted series from the price-history exports — no FX assumption applied by us.
A6: Market Data & Enterprise Value Build
B7: Ticker | C7: Share Price ($) | D7: Diluted Shares (mm) | E7: Market Cap ($mm) | F7: Total Debt ($mm) | G7: Cash & Equiv. ($mm) | H7: Minority Int. ($mm) | I7: Preferred Eq. ($mm) | J7: Enterprise Value ($mm) | K7: Source Notes | N7: Beta (5y monthly vs S&P 500) | O7: As entered (local ccy) | P7: Implied FX
A8: Micron Technology, Inc. | B8: MU | C8: 924.03 | D8: 1145 | E8: =C8*D8 -> 1058014.3 | F8: 5722 | G8: 30200 | H8: 0 | J8: =E8+F8-G8+IF(H8="",0,H8)+IF(I8="",0,I8) -> 1033536.3 | N8: 2.25
A10: SK hynix Inc. | B10: 000660.KS | C10: 1254.61 | D10: 711 | E10: =C10*D10 -> 892027.71 | F10: 18472 | G10: 26046 | H10: 0 | J10: =E10+F10-G10+IF(H10="",0,H10)+IF(I10="",0,I10) -> 884453.71 | K10: KRW -> USD @ 1,340.30; FY end 2025-12-31 | N10: 1.8 | O10: 1690000 | P10: 1347.03
A11: Samsung Electronics Co. | B11: 005930.KS | C11: 184.48 | D11: 6703 | E11: =C11*D11 -> 1236569.4 | F11: 18831 | G11: 93895 | H11: 0 | J11: =E11+F11-G11+IF(H11="",0,H11)+IF(I11="",0,I11) -> 1161505.4 | K11: KRW -> USD @ 1,340.30; FY end 2025-12-31 | N11: 1.23 | O11: 248500 | P11: 1347.03
A12: Kioxia Holdings Corp. | B12: 285A.T | C12: 335.28 | D12: 549 | E12: =C12*D12 -> 184068.72 | F12: 8153 | G12: 3109 | H12: 0 | J12: =E12+F12-G12+IF(H12="",0,H12)+IF(I12="",0,I12) -> 189112.72 | K12: JPY -> USD @ 153.71; FY end 2026-03-31 | N12: 1.73 | O12: 51750 | P12: 154.35
A13: Peer Mean | B13: SNDK | C13: 1530.89 | D13: 155 | E13: =C13*D13 -> 237287.95 | F13: 0 | G13: 4762 | H13: 0 | J13: =E13+F13-G13+IF(H13="",0,H13)+IF(I13="",0,I13) -> 232525.95 | K13: USD -> USD @ 1.00; FY end 2026-07-03 | N13: 2.6 | O13: 1530.895 | P13: 1
C14: 14.66 | D14: 3152 | E14: =C14*D14 -> 46208.32 | F14: 746 | G14: 1835 | H14: 0 | J14: =E14+F14-G14+IF(H14="",0,H14)+IF(I14="",0,I14) -> 45119.32 | K14: TWD -> USD @ 31.64; FY end 2025-12-31 | N14: 1.89 | O14: 465.5 | P14: 31.75
C15: 411.96 | D15: 383 | E15: =C15*D15 -> 157780.68 | F15: 1052 | G15: 1579 | H15: 0 | J15: =E15+F15-G15+IF(H15="",0,H15)+IF(I15="",0,I15) -> 157253.68 | K15: USD -> USD @ 1.00; FY end 2026-07-03 | N15: 2.13 | O15: 411.96 | P15: 1
C17: =IFERROR(AVERAGE(C10:C15),"") -> 621.98 | D17: =IFERROR(AVERAGE(D10:D15),"") -> 1942.1667 | E17: =IFERROR(AVERAGE(E10:E15),"") -> 458990.47 | F17: =IFERROR(AVERAGE(F10:F15),"") -> 7875.6667 | G17: =IFERROR(AVERAGE(G10:G15),"") -> 21871 | H17: =IFERROR(AVERAGE(H10:H15),"") -> 0 | I17: =IFERROR(AVERAGE(I10:I15),"") | J17: =IFERROR(AVERAGE(J10:J15),"") -> 444995.14
A18: Peer Median | C18: =IFERROR(MEDIAN(C10:C15),"") -> 373.62 | D18: =IFERROR(MEDIAN(D10:D15),"") -> 630 | E18: =IFERROR(MEDIAN(E10:E15),"") -> 210678.33 | F18: =IFERROR(MEDIAN(F10:F15),"") -> 4602.5 | G18: =IFERROR(MEDIAN(G10:G15),"") -> 3935.5 | H18: =IFERROR(MEDIAN(H10:H15),"") -> 0 | I18: =IFERROR(MEDIAN(I10:I15),"") | J18: =IFERROR(MEDIAN(J10:J15),"") -> 210819.33
A19: Peer High | C19: =IFERROR(MAX(C10:C15),"") -> 1530.89 | D19: =IFERROR(MAX(D10:D15),"") -> 6703 | E19: =IFERROR(MAX(E10:E15),"") -> 1236569.4 | F19: =IFERROR(MAX(F10:F15),"") -> 18831 | G19: =IFERROR(MAX(G10:G15),"") -> 93895 | H19: =IFERROR(MAX(H10:H15),"") -> 0 | I19: =IFERROR(MAX(I10:I15),"") -> 0 | J19: =IFERROR(MAX(J10:J15),"") -> 1161505.4
A20: Peer Low | C20: =IFERROR(MIN(C10:C15),"") -> 14.66 | D20: =IFERROR(MIN(D10:D15),"") -> 155 | E20: =IFERROR(MIN(E10:E15),"") -> 46208.32 | F20: =IFERROR(MIN(F10:F15),"") -> 0 | G20: =IFERROR(MIN(G10:G15),"") -> 1579 | H20: =IFERROR(MIN(H10:H15),"") -> 0 | I20: =IFERROR(MIN(I10:I15),"") -> 0 | J20: =IFERROR(MIN(J10:J15),"") -> 45119.32
A22: Reporting currency / FX note
A23: Peers report in KRW (SK hynix, Samsung), JPY (Kioxia), TWD (Nanya). Enter USD-converted figures and record the FX rate and date used below.
A24: FX rates used (state date):
A26: CORRECTED 16 Sep: prices had been entered in local currency (KRW/JPY/TWD), which would have produced
A27: local-currency market caps against USD debt and cash. Implied FX in column P reconciles to spot within 0.5%,
A28: which independently validates both the entries and LSEG’s conversion. Columns O and P retain the originals.
A29: multiple in this workbook meaningless. Pull current prices for all seven names on ONE date.

Sheet Financial Data
A1: Micron Technology, Inc. (NASDAQ: MU)
A2: Trading Comparable Companies Analysis
A4: Latest reported fiscal year per company, converted to USD $mm. Period-end dates differ - see notes column.
B5: Ticker | C5: Revenue | D5: Gross Profit | E5: Gross Margin | F5: EBITDA | G5: EBITDA Margin | H5: EBIT | I5: EBIT Margin | J5: Net Income | K5: Oper. Cash Flow | L5: CapEx | M5: Free Cash Flow | N5: FCF Margin | O5: Source
A6: Micron Technology, Inc. | B6: MU | C6: 90274 | D6: 65505 | E6: =D6/C6 -> 0.72562421 | F6: 68254 | G6: =F6/C6 -> 0.75607595 | H6: 59054 | I6: =H6/C6 -> 0.65416399 | J6: 50469 | K6: 63929 | L6: -37757 | M6: =K6+L6 -> 26172 | N6: =IF(M6=0,"-",M6/C6) -> 0.28991736
A8: SK hynix Inc. | B8: 000660.KS | C8: 72481 | D8: 43759 | E8: =D8/C8 -> 0.60373063 | F8: 45584 | G8: =F8/C8 -> 0.62890965 | H8: 35191 | I8: =H8/C8 -> 0.48552034 | J8: 32043 | K8: 39822 | L8: -21150 | M8: =K8+L8 -> 18672 | N8: =IF(M8=0,"-",M8/C8) -> 0.25761234 | O8: FY end 2025-12-31 | KRW
A9: Samsung Electronics Co. | B9: 005930.KS | C9: 248904 | D9: 98016 | E9: =D9/C9 -> 0.39379038 | F9: 67543 | G9: =F9/C9 -> 0.27136165 | H9: 32531 | I9: =H9/C9 -> 0.13069698 | J9: 33729 | K9: 63654 | L9: -38790 | M9: =K9+L9 -> 24864 | N9: =IF(M9=0,"-",M9/C9) -> 0.099893935 | O9: FY end 2025-12-31 | KRW
A10: Kioxia Holdings Corp. | B10: 285A.T | C10: 15208 | D10: 7170 | E10: =D10/C10 -> 0.47146239 | F10: 7689 | G10: =F10/C10 -> 0.50558916 | H10: 5654 | I10: =H10/C10 -> 0.37177801 | J10: 3607 | K10: 4011 | L10: -1805 | M10: =K10+L10 -> 2206 | N10: =IF(M10=0,"-",M10/C10) -> 0.14505523 | O10: FY end 2026-03-31 | JPY
A11: SanDisk Corporation | B11: SNDK | C11: 20248 | D11: 14472 | E11: =D11/C11 -> 0.71473726 | F11: 12617 | G11: =F11/C11 -> 0.62312327 | H11: 12468 | I11: =H11/C11 -> 0.61576452 | J11: 11423 | K11: 11671 | L11: -177 | M11: =K11+L11 -> 11494 | N11: =IF(M11=0,"-",M11/C11) -> 0.567661 | O11: FY end 2026-07-03 | USD
A12: Nanya Technology Corp. | B12: 2408.TW | C12: 2105 | D12: 474 | E12: =D12/C12 -> 0.22517815 | F12: 617 | G12: =F12/C12 -> 0.29311164 | H12: 166 | I12: =H12/C12 -> 0.078859857 | J12: 209 | K12: 593 | L12: -432 | M12: =K12+L12 -> 161 | N12: =IF(M12=0,"-",M12/C12) -> 0.076484561 | O12: FY end 2025-12-31 | TWD
A13: Western Digital Corp. | B13: WDC | C13: 12919 | D13: 6311 | E13: =D13/C13 -> 0.4885053 | F13: 4974 | G13: =F13/C13 -> 0.38501432 | H13: 4599 | I13: =H13/C13 -> 0.35598731 | J13: 9424 | K13: 3929 | L13: -418 | M13: =K13+L13 -> 3511 | N13: =IF(M13=0,"-",M13/C13) -> 0.27177026 | O13: FY end 2026-07-03 | USD
A15: Peer Mean | C15: =AVERAGE(C8:C13) -> 61977.5 | D15: =AVERAGE(D8:D13) -> 28367 | E15: =AVERAGE(E8:E13) -> 0.48290068 | F15: =AVERAGE(F8:F13) -> 23170.667 | G15: =AVERAGE(G8:G13) -> 0.45118495 | H15: =AVERAGE(H8:H13) -> 15101.5 | I15: =AVERAGE(I8:I13) -> 0.33976784 | J15: =AVERAGE(J8:J13) -> 15072.5 | ... N15: =AVERAGE(N8:N13) -> 0.23641289
A16: Peer Median | C16: =MEDIAN(C8:C13) -> 17728 | D16: =MEDIAN(D8:D13) -> 10821 | E16: =MEDIAN(E8:E13) -> 0.47998385 | F16: =MEDIAN(F8:F13) -> 10153 | G16: =MEDIAN(G8:G13) -> 0.44530174 | H16: =MEDIAN(H8:H13) -> 9061 | I16: =MEDIAN(I8:I13) -> 0.36388266 | J16: =MEDIAN(J8:J13) -> 10423.5 | ... N16: =MEDIAN(N8:N13) -> 0.20133379
A17: Peer High | C17: =MAX(C8:C13) -> 248904 | D17: =MAX(D8:D13) -> 98016 | E17: =MAX(E8:E13) -> 0.71473726 | F17: =MAX(F8:F13) -> 67543 | G17: =MAX(G8:G13) -> 0.62890965 | H17: =MAX(H8:H13) -> 35191 | I17: =MAX(I8:I13) -> 0.61576452 | J17: =MAX(J8:J13) -> 33729 | ... N17: =MAX(N8:N13) -> 0.567661
A18: Peer Low | C18: =MIN(C8:C13) -> 2105 | D18: =MIN(D8:D13) -> 474 | E18: =MIN(E8:E13) -> 0.22517815 | F18: =MIN(F8:F13) -> 617 | G18: =MIN(G8:G13) -> 0.27136165 | H18: =MIN(H8:H13) -> 166 | I18: =MIN(I8:I13) -> 0.078859857 | J18: =MIN(J8:J13) -> 209 | ... N18: =MIN(N8:N13) -> 0.076484561
A20: Forward Consensus Estimates (LSEG I/B/E/S) — calendarised to a common NTM window
A21: Company | B21: Ticker | C21: Consensus FY used | D21: FY midpoint offset (mo) | E21: NTM Revenue ($mm) | F21: NTM EBITDA ($mm) | G21: NTM EPS ($) | H21: NTM EBITDA margin | I21: Nearest-FY EV/EBITDA | J21: Interpolated EV/EBITDA
A22: Micron Technology, Inc. | B22: MU | C22: FY Aug-27 | D22: -0.5 | E22: 250548 | F22: 228137.1 | G22: 155.25 | H22: =IFERROR(F22/E22,"") -> 0.91055247 | I22: 4.55 | J22: 4.53
A24: SK hynix Inc. | B24: 000660.KS | C24: FY Dec-27 | D24: 3.5 | E24: 353870.4 | F24: 292927.4 | G24: 323.07 | H24: =IFERROR(F24/E24,"") -> 0.82778158 | I24: 2.72 | J24: 3.02
A25: Samsung Electronics Co. | B25: 005930.KS | C25: FY Dec-27 | D25: 3.5 | E25: 672199.6 | F25: 419369.1 | G25: 47.18 | H25: =IFERROR(F25/E25,"") -> 0.62387585 | I25: 2.53 | J25: 2.77
A26: Kioxia Holdings Corp. | B26: 285A.T | C26: FY Mar-27 | D26: -5.6 | E26: 74498 | F26: 60685.8 | G26: 77.07 | H26: =IFERROR(F26/E26,"") -> 0.81459637 | I26: 3.51 | J26: 3.12
A27: SanDisk Corporation | B27: SNDK | C27: FY Jun-27 | D27: -2.5 | E27: 51027 | F27: 41351.4 | G27: 232.95 | H27: =IFERROR(F27/E27,"") -> 0.81038274 | I27: 5.85 | J27: 5.62
A28: Nanya Technology Corp. | B28: 2408.TW | C28: FY Dec-27 | D28: 3.5 | E28: 15475.5 | F28: 12036.8 | G28: 2.91 | H28: =IFERROR(F28/E28,"") -> 0.77779716 | I28: 3.36 | J28: 3.75
A29: Western Digital Corp. | B29: WDC | C29: FY Jun-27 | D29: -2.5 | E29: 20707.8 | F29: 11350.8 | G29: 22.49 | H29: =IFERROR(F29/E29,"") -> 0.54814128 | I29: 15.44 | J29: 13.85
A31: Peer Mean | E31: =IFERROR(AVERAGE(E24:E29),"") -> 197963.05 | F31: =IFERROR(AVERAGE(F24:F29),"") -> 139620.22 | G31: =IFERROR(AVERAGE(G24:G29),"") -> 117.61167 | H31: =IFERROR(AVERAGE(H24:H29),"") -> 0.7337625 | I31: =IFERROR(AVERAGE(I24:I29),"") -> 5.5683333 | J31: =IFERROR(AVERAGE(J24:J29),"") -> 5.355
A32: Peer Median | E32: =IFERROR(MEDIAN(E24:E29),"") -> 62762.5 | F32: =IFERROR(MEDIAN(F24:F29),"") -> 51018.6 | G32: =IFERROR(MEDIAN(G24:G29),"") -> 62.125 | H32: =IFERROR(MEDIAN(H24:H29),"") -> 0.79408995 | I32: =IFERROR(MEDIAN(I24:I29),"") -> 3.435 | J32: =IFERROR(MEDIAN(J24:J29),"") -> 3.435
A33: Micron premium / (discount) to peer median | I33: =IFERROR((I22/I32)-1,"") -> 0.32459971 | J33: =IFERROR((J22/J32)-1,"") -> 0.31877729
A35: Growth & Profitability Benchmarking
B36: Ticker | C36: 3-Yr Rev CAGR | D36: 3-Yr EBITDA CAGR | E36: ROIC | F36: ROA | G36: Net Debt/EBITDA | H36: Interest cov. | I36: Employees | J36: Rev/Employee ($K)
A37: Micron Technology, Inc. | B37: MU | C37: 0.0671 | D37: 0.0276 | E37: 0.1408 | F37: 0.1122 | G37: =('Market Data'!F8-'Market Data'!G8)/'Financial Data'!F6 -> -0.358631 | H37: 20.7 | I37: 50500 | J37: =IFERROR('Financial Data'!C6/I37*1000,"") -> 1787.604
A39: SK hynix Inc. | B39: 000660.KS | C39: 0.2961 | D39: 0.4285 | E39: 0.3571 | F39: 0.2902 | G39: -0.17 | H39: 51.1 | J39: =IFERROR('Financial Data'!C8/I39*1000,"")
A40: Samsung Electronics Co. | B40: 005930.KS | C40: 0.0335 | D40: 0.0315 | E40: 0.1015 | F40: 0.0836 | G40: -1.11 | H40: 72 | J40: =IFERROR('Financial Data'!C9/I40*1000,"")
A41: Kioxia Holdings Corp. | B41: 285A.T | C41: 0.2217 | D41: 0.5445 | E41: 0.2759 | F41: 0.1678 | G41: 0.66 | H41: 12 | I41: 15130 | J41: =IFERROR('Financial Data'!C10/I41*1000,"") -> 1005.1553
A42: SanDisk Corporation | B42: SNDK | C42: 0.4929 | E42: 0.858 | F42: 0.6437 | G42: -0.38 | H42: 170.8 | I42: 11050 | J42: =IFERROR('Financial Data'!C11/I42*1000,"") -> 1832.3982
A43: Nanya Technology Corp. | B43: 2408.TW | C43: 0.0535 | D43: -0.0939 | E43: 0.0365 | F43: 0.0319 | G43: -1.76 | H43: 9.2 | J43: =IFERROR('Financial Data'!C12/I43*1000,"")
A44: Western Digital Corp. | B44: WDC | C44: 0.2735 | E44: 0.9502 | F44: 0.6765 | G44: -0.11 | H44: 27.9 | I44: 40000 | J44: =IFERROR('Financial Data'!C13/I44*1000,"") -> 322.975
A46: Peer Mean | C46: =IFERROR(AVERAGE(C39:C44),"") -> 0.22853333 | D46: =IFERROR(AVERAGE(D39:D44),"") -> 0.22765 | E46: =IFERROR(AVERAGE(E39:E44),"") -> 0.42986667 | F46: =IFERROR(AVERAGE(F39:F44),"") -> 0.31561667 | G46: =IFERROR(AVERAGE(G39:G44),"") -> -0.47833333 | H46: =IFERROR(AVERAGE(H39:H44),"") -> 57.166667 | I46: =IFERROR(AVERAGE(I39:I44),"") -> 22060 | J46: =IFERROR(AVERAGE(J39:J44),"") -> 1053.5095
A47: Peer Median | C47: =IFERROR(MEDIAN(C39:C44),"") -> 0.2476 | D47: =IFERROR(MEDIAN(D39:D44),"") -> 0.23 | E47: =IFERROR(MEDIAN(E39:E44),"") -> 0.3165 | F47: =IFERROR(MEDIAN(F39:F44),"") -> 0.229 | G47: =IFERROR(MEDIAN(G39:G44),"") -> -0.275 | H47: =IFERROR(MEDIAN(H39:H44),"") -> 39.5 | I47: =IFERROR(MEDIAN(I39:I44),"") -> 15130 | J47: =IFERROR(MEDIAN(J39:J44),"") -> 1005.1553
A49: Forward-estimate methodology note
A50: Method. LSEG I/B/E/S mean estimates, pulled 16 Sep 2026 for all seven names on one date. Foreign-currency estimates converted at 16 Sep spot
...

Sheet Valuation Multiples
A1: Micron Technology, Inc. (NASDAQ: MU)
A2: Trading Comparable Companies Analysis
A4: Last Twelve Months Valuation Multiples
B5: Ticker | C5: EV / Rev | D5: EV / GP | E5: EV / EBITDA | F5: EV / EBIT | G5: P / E | H5: P / FCF | I5: FCF Yield
A6: Micron Technology, Inc. | B6: MU | C6: =IFERROR('Market Data'!J8/'Financial Data'!C6,"") -> 11.448882 | D6: =IFERROR('Market Data'!J8/'Financial Data'!D6,"") -> 15.777976 | E6: =IFERROR('Market Data'!J8/'Financial Data'!F6,"") -> 15.142502 | F6: =IFERROR('Market Data'!J8/'Financial Data'!H6,"") -> 17.501547 | G6: =IFERROR('Market Data'!E8/'Financial Data'!J6,"") -> 20.963648 | H6: N/M | I6: =IFERROR('Financial Data'!M6/'Market Data'!E8,"") -> 0.024736905
A8: SK hynix Inc. | B8: 000660.KS | C8: =IFERROR('Market Data'!J10/'Financial Data'!C8,"") -> 12.202559 | D8: =IFERROR('Market Data'!J10/'Financial Data'!D8,"") -> 20.211927 | E8: =IFERROR('Market Data'!J10/'Financial Data'!F8,"") -> 19.402723 | F8: =IFERROR('Market Data'!J10/'Financial Data'!H8,"") -> 25.132952 | G8: =IFERROR('Market Data'!E10/'Financial Data'!J8,"") -> 27.838458 | H8: =IFERROR('Market Data'!E10/'Financial Data'!M8,"") -> 47.773549 | I8: =IFERROR('Financial Data'!M8/'Market Data'!E10,"") -> 0.020932085
A9: Samsung Electronics Co. | B9: 005930.KS | C9: =IFERROR('Market Data'!J11/'Financial Data'!C9,"") -> 4.6664796 | D9: =IFERROR('Market Data'!J11/'Financial Data'!D9,"") -> 11.850162 | E9: =IFERROR('Market Data'!J11/'Financial Data'!F9,"") -> 17.196533 | F9: =IFERROR('Market Data'!J11/'Financial Data'!H9,"") -> 35.704572 | G9: =IFERROR('Market Data'!E11/'Financial Data'!J9,"") -> 36.661906 | H9: =IFERROR('Market Data'!E11/'Financial Data'!M9,"") -> 49.733327 | I9: =IFERROR('Financial Data'!M9/'Market Data'!E11,"") -> 0.020107241
A10: Kioxia Holdings Corp. | B10: 285A.T | C10: =IFERROR('Market Data'!J12/'Financial Data'!C10,"") -> 12.435082 | D10: =IFERROR('Market Data'!J12/'Financial Data'!D10,"") -> 26.375554 | E10: =IFERROR('Market Data'!J12/'Financial Data'!F10,"") -> 24.59523 | F10: =IFERROR('Market Data'!J12/'Financial Data'!H10,"") -> 33.447598 | G10: =IFERROR('Market Data'!E12/'Financial Data'!J10,"") -> 51.030973 | H10: =IFERROR('Market Data'!E12/'Financial Data'!M10,"") -> 83.440036 | I10: =IFERROR('Financial Data'!M10/'Market Data'!E12,"") -> 0.011984654
A11: SanDisk Corporation | B11: SNDK | C11: =IFERROR('Market Data'!J13/'Financial Data'!C11,"") -> 11.483897 | D11: =IFERROR('Market Data'!J13/'Financial Data'!D11,"") -> 16.067299 | E11: =IFERROR('Market Data'!J13/'Financial Data'!F11,"") -> 18.429575 | F11: =IFERROR('Market Data'!J13/'Financial Data'!H11,"") -> 18.64982 | G11: =IFERROR('Market Data'!E13/'Financial Data'!J11,"") -> 20.772822 | H11: =IFERROR('Market Data'!E13/'Financial Data'!M11,"") -> 20.644506 | I11: =IFERROR('Financial Data'!M11/'Market Data'!E13,"") -> 0.048439038
A12: Nanya Technology Corp. | B12: 2408.TW | C12: =IFERROR('Market Data'!J14/'Financial Data'!C12,"") -> 21.434356 | D12: =IFERROR('Market Data'!J14/'Financial Data'!D12,"") -> 95.188439 | E12: =IFERROR('Market Data'!J14/'Financial Data'!F12,"") -> 73.126937 | F12: =IFERROR('Market Data'!J14/'Financial Data'!H12,"") -> 271.80313 | G12: =IFERROR('Market Data'!E14/'Financial Data'!J12,"") -> 221.09244 | H12: =IFERROR('Market Data'!E14/'Financial Data'!M12,"") -> 287.0082 | I12: =IFERROR('Financial Data'!M12/'Market Data'!E14,"") -> 0.003484221
A13: Western Digital Corp. | B13: WDC | C13: =IFERROR('Market Data'!J15/'Financial Data'!C13,"") -> 12.17228 | D13: =IFERROR('Market Data'!J15/'Financial Data'!D13,"") -> 24.917395 | E13: =IFERROR('Market Data'!J15/'Financial Data'!F13,"") -> 31.615135 | F13: =IFERROR('Market Data'!J15/'Financial Data'!H13,"") -> 34.193016 | G13: =IFERROR('Market Data'!E15/'Financial Data'!J13,"") -> 16.742432 | H13: =IFERROR('Market Data'!E15/'Financial Data'!M13,"") -> 44.938958 | I13: =IFERROR('Financial Data'!M13/'Market Data'!E15,"") -> 0.022252408
A15: Peer Mean | C15: =IFERROR(AVERAGE(C8:C13),"") -> 12.399109 | D15: =IFERROR(AVERAGE(D8:D13),"") -> 32.435129 | E15: =IFERROR(AVERAGE(E8:E13),"") -> 30.727689 | F15: =IFERROR(AVERAGE(F8:F13),"") -> 69.821848 | G15: =IFERROR(AVERAGE(G8:G13),"") -> 62.356505 | H15: =IFERROR(AVERAGE(H8:H13),"") -> 88.923096 | I15: =IFERROR(AVERAGE(I8:I13),"") -> 0.021199941
A16: Peer Median | C16: =IFERROR(MEDIAN(C8:C13),"") -> 12.18742 | D16: =IFERROR(MEDIAN(D8:D13),"") -> 22.564661 | E16: =IFERROR(MEDIAN(E8:E13),"") -> 21.998976 | F16: =IFERROR(MEDIAN(F8:F13),"") -> 33.820307 | G16: =IFERROR(MEDIAN(G8:G13),"") -> 32.250182 | H16: =IFERROR(MEDIAN(H8:H13),"") -> 48.753438 | I16: =IFERROR(MEDIAN(I8:I13),"") -> 0.020519663
A17: Peer High | C17: =IFERROR(MAX(C8:C13),"") -> 21.434356 | D17: =IFERROR(MAX(D8:D13),"") -> 95.188439 | E17: =IFERROR(MAX(E8:E13),"") -> 73.126937 | F17: =IFERROR(MAX(F8:F13),"") -> 271.80313 | G17: =IFERROR(MAX(G8:G13),"") -> 221.09244 | H17: =IFERROR(MAX(H8:H13),"") -> 287.0082 | I17: =IFERROR(MAX(I8:I13),"") -> 0.048439038
A18: Peer Low | C18: =IFERROR(MIN(C8:C13),"") -> 4.6664796 | D18: =IFERROR(MIN(D8:D13),"") -> 11.850162 | E18: =IFERROR(MIN(E8:E13),"") -> 17.196533 | F18: =IFERROR(MIN(F8:F13),"") -> 18.64982 | G18: =IFERROR(MIN(G8:G13),"") -> 16.742432 | H18: =IFERROR(MIN(H8:H13),"") -> 20.644506 | I18: =IFERROR(MIN(I8:I13),"") -> 0.003484221
A19: Micron Premium / (Discount) to Peer Median | C19: =IFERROR((C6/C16)-1,"") -> -0.060598371 | D19: =IFERROR((D6/D16)-1,"") -> -0.30076607 | E19: =IFERROR((E6/E16)-1,"") -> -0.31167241 | F19: =IFERROR((F6/F16)-1,"") -> -0.48251366 | G19: =IFERROR((G6/G16)-1,"") -> -0.34996808 | H19: N/M | I19: =IFERROR((I6/I16)-1,"") -> 0.20552196
A21: Forward multiples below are calendarised to a common NTM window (midpoint 15 March 2027). See the methodology note on “Financial Data”.
A22: Forward (Next Twelve Months) Valuation Multiples — calendarised
A23: Company | B23: Ticker | C23: NTM EV / Rev | D23: NTM EV / EBITDA | E23: NTM P / E | F23: NTM EBITDA margin | G23: Consensus FY used | H23: Offset (mo)
A24: Micron Technology, Inc. | B24: MU | C24: =IFERROR('Market Data'!J8/'Financial Data'!E22,"") -> 4.1251032 | D24: =IFERROR('Market Data'!J8/'Financial Data'!F22,"") -> 4.53033 | E24: =IFERROR('Market Data'!C8/'Financial Data'!G22,"") -> 5.9518841 | F24: =IFERROR('Financial Data'!H22,"") -> 0.91055247 | G24: =IFERROR('Financial Data'!C22,"") -> FY Aug-27 | H24: =IFERROR('Financial Data'!D22,"") -> -0.5
A26: SK hynix Inc. | B26: 000660.KS | C26: =IFERROR('Market Data'!J10/'Financial Data'!E24,"") -> 2.4993718 | D26: =IFERROR('Market Data'!J10/'Financial Data'!F24,"") -> 3.0193615 | E26: =IFERROR('Market Data'!C10/'Financial Data'!G24,"") -> 3.8833999 | F26: =IFERROR('Financial Data'!H24,"") -> 0.82778158 | G26: =IFERROR('Financial Data'!C24,"") -> FY Dec-27 | H26: =IFERROR('Financial Data'!D24,"") -> 3.5
A27: Samsung Electronics Co. | B27: 005930.KS | C27: =IFERROR('Market Data'!J11/'Financial Data'!E25,"") -> 1.7279175 | D27: =IFERROR('Market Data'!J11/'Financial Data'!F25,"") -> 2.7696496 | E27: =IFERROR('Market Data'!C11/'Financial Data'!G25,"") -> 3.9101314 | F27: =IFERROR('Financial Data'!H25,"") -> 0.62387585 | G27: =IFERROR('Financial Data'!C25,"") -> FY Dec-27 | H27: =IFERROR('Financial Data'!D25,"") -> 3.5
A28: Kioxia Holdings Corp. | B28: 285A.T | C28: =IFERROR('Market Data'!J12/'Financial Data'!E26,"") -> 2.5384939 | D28: =IFERROR('Market Data'!J12/'Financial Data'!F26,"") -> 3.1162598 | E28: =IFERROR('Market Data'!C12/'Financial Data'!G26,"") -> 4.3503309 | F28: =IFERROR('Financial Data'!H26,"") -> 0.81459637 | G28: =IFERROR('Financial Data'!C26,"") -> FY Mar-27 | H28: =IFERROR('Financial Data'!D26,"") -> -5.6
A29: SanDisk Corporation | B29: SNDK | C29: =IFERROR('Market Data'!J13/'Financial Data'!E27,"") -> 4.5569199 | D29: =IFERROR('Market Data'!J13/'Financial Data'!F27,"") -> 5.62317 | E29: =IFERROR('Market Data'!C13/'Financial Data'!G27,"") -> 6.5717536 | F29: =IFERROR('Financial Data'!H27,"") -> 0.81038274 | G29: =IFERROR('Financial Data'!C27,"") -> FY Jun-27 | H29: =IFERROR('Financial Data'!D27,"") -> -2.5
A30: Nanya Technology Corp. | B30: 2408.TW | C30: =IFERROR('Market Data'!J14/'Financial Data'!E28,"") -> 2.9155323 | D30: =IFERROR('Market Data'!J14/'Financial Data'!F28,"") -> 3.7484481 | E30: =IFERROR('Market Data'!C14/'Financial Data'!G28,"") -> 5.0378007 | F30: =IFERROR('Financial Data'!H28,"") -> 0.77779716 | G30: =IFERROR('Financial Data'!C28,"") -> FY Dec-27 | H30: =IFERROR('Financial Data'!D28,"") -> 3.5
A31: Western Digital Corp. | B31: WDC | C31: =IFERROR('Market Data'!J15/'Financial Data'!E29,"") -> 7.5939347 | D31: =IFERROR('Market Data'!J15/'Financial Data'!F29,"") -> 13.853973 | E31: =IFERROR('Market Data'!C15/'Financial Data'!G29,"") -> 18.317474 | F31: =IFERROR('Financial Data'!H29,"") -> 0.54814128 | G31: =IFERROR('Financial Data'!C29,"") -> FY Jun-27 | H31: =IFERROR('Financial Data'!D29,"") -> -2.5
A33: Peer Mean | C33: =IFERROR(AVERAGE(C26:C31),"") -> 3.638695 | D33: =IFERROR(AVERAGE(D26:D31),"") -> 5.3551437 | E33: =IFERROR(AVERAGE(E26:E31),"") -> 7.0118151 | F33: =IFERROR(AVERAGE(F26:F31),"") -> 0.7337625
A34: Peer Median | C34: =IFERROR(MEDIAN(C26:C31),"") -> 2.7270131 | D34: =IFERROR(MEDIAN(D26:D31),"") -> 3.432354 | E34: =IFERROR(MEDIAN(E26:E31),"") -> 4.6940658 | F34: =IFERROR(MEDIAN(F26:F31),"") -> 0.79408995
A35: Peer High | C35: =IFERROR(MAX(C26:C31),"") -> 7.5939347 | D35: =IFERROR(MAX(D26:D31),"") -> 13.853973 | E35: =IFERROR(MAX(E26:E31),"") -> 18.317474 | F35: =IFERROR(MAX(F26:F31),"") -> 0.82778158
A36: Peer Low | C36: =IFERROR(MIN(C26:C31),"") -> 1.7279175 | D36: =IFERROR(MIN(D26:D31),"") -> 2.7696496 | E36: =IFERROR(MIN(E26:E31),"") -> 3.8833999 | F36: =IFERROR(MIN(F26:F31),"") -> 0.54814128
A37: Micron Premium / (Discount) to Peer Median | C37: =IFERROR((C24/C34)-1,"") -> 0.51268183 | D37: =IFERROR((D24/D34)-1,"") -> 0.3198901 | E37: =IFERROR((E24/E34)-1,"") -> 0.26795924 | F37: =IFERROR((F24/F34)-1,"") -> 0.14666162
A39: Cross-check on the unadjusted (nearest-fiscal-year) basis, no interpolation:
A40: NTM EV/EBITDA — Micron | B40: =IFERROR('Financial Data'!I22,"") -> 4.55
A41: NTM EV/EBITDA — peer median | B41: =IFERROR('Financial Data'!I32,"") -> 3.435
A42: Premium / (discount) | B42: =IFERROR('Financial Data'!I33,"") -> 0.32459971
A43: The interpolated and unadjusted bases agree to within one point of relative premium, so the result is not a fiscal-year artefact.

Sheet Implied Valuation
A1: Micron Technology, Inc. (NASDAQ: MU)
A2: Comparable Companies Implied Valuation
A4: Implied Enterprise Value from Peer Multiples ($mm)
A5: Methodology | B5: Low (25th Pctl) | C5: Median | D5: High (75th Pctl) | E5: Mean | F5: Notes
A6: LTM EV / Revenue | B6: =IFERROR(QUARTILE('Valuation Multiples'!C8:C13,1)*'Financial Data'!C6,"") -> 1052233.1 | C6: =IFERROR(MEDIAN('Valuation Multiples'!C8:C13)*'Financial Data'!C6,"") -> 1100207.1 | D6: =IFERROR(QUARTILE('Valuation Multiples'!C8:C13,3)*'Financial Data'!C6,"") -> 1117316.9 | E6: =IFERROR(AVERAGE('Valuation Multiples'!C8:C13)*'Financial Data'!C6,"") -> 1119317.2
A7: LTM EV / EBITDA | B7: =IFERROR(QUARTILE('Valuation Multiples'!E8:E13,1)*'Financial Data'!F6,"") -> 1274497.5 | C7: =IFERROR(MEDIAN('Valuation Multiples'!E8:E13)*'Financial Data'!F6,"") -> 1501518.1 | D7: =IFERROR(QUARTILE('Valuation Multiples'!E8:E13,3)*'Financial Data'!F6,"") -> 2038075.3 | E7: =IFERROR(AVERAGE('Valuation Multiples'!E8:E13)*'Financial Data'!F6,"") -> 2097287.7
A8: LTM EV / EBIT | B8: =IFERROR(QUARTILE('Valuation Multiples'!F8:F13,1)*'Financial Data'!H6,"") -> 1606954.6 | C8: =IFERROR(MEDIAN('Valuation Multiples'!F8:F13)*'Financial Data'!H6,"") -> 1997224.4 | D8: =IFERROR(QUARTILE('Valuation Multiples'!F8:F13,3)*'Financial Data'!H6,"") -> 2086181.9 | E8: =IFERROR(AVERAGE('Valuation Multiples'!F8:F13)*'Financial Data'!H6,"") -> 4123259.4
A9: NTM EV / Revenue (calendarised) | B9: =IFERROR(QUARTILE('Valuation Multiples'!C26:C31,1)*'Financial Data'!E22,"") -> 628663.1 | C9: =IFERROR(MEDIAN('Valuation Multiples'!C26:C31)*'Financial Data'!E22,"") -> 683247.68 | D9: =IFERROR(QUARTILE('Valuation Multiples'!C26:C31,3)*'Financial Data'!E22,"") -> 1038915.6 | E9: =IFERROR(AVERAGE('Valuation Multiples'!C26:C31)*'Financial Data'!E22,"") -> 911667.76 | F9: Peer multiple applied to Micron NTM revenue
A10: NTM EV / EBITDA (calendarised) | B10: =IFERROR(QUARTILE('Valuation Multiples'!D26:D31,1)*'Financial Data'!F22,"") -> 694354.9 | C10: =IFERROR(MEDIAN('Valuation Multiples'!D26:D31)*'Financial Data'!F22,"") -> 783047.28 | D10: =IFERROR(QUARTILE('Valuation Multiples'!D26:D31,3)*'Financial Data'!F22,"") -> 1175930.3 | E10: =IFERROR(AVERAGE('Valuation Multiples'!D26:D31)*'Financial Data'!F22,"") -> 1221707 | F10: Primary forward cross-check on the DCF
A13: Enterprise Value to Equity Value Bridge
A14: Selected Implied Enterprise Value — Low ($mm) | B14: =IFERROR(QUARTILE('Valuation Multiples'!E8:E13,1)*'Financial Data'!F6,"") -> 1274497.5 | C14: Selected on LTM EV/EBITDA. Cross-check only — the recommendation rests on the DCF.
A15: Selected Implied Enterprise Value — Base ($mm) | B15: =IFERROR(MEDIAN('Valuation Multiples'!E8:E13)*'Financial Data'!F6,"") -> 1501518.1
A16: Selected Implied Enterprise Value — High ($mm) | B16: =IFERROR(QUARTILE('Valuation Multiples'!E8:E13,3)*'Financial Data'!F6,"") -> 2038075.3
A18: Less: Total Debt ($mm) | B18: 5722
A19: Less: Minority Interest ($mm) | B19: 0
A20: Plus: Cash and Cash Equivalents ($mm) | B20: 30200
A22: Implied Equity Value — Low ($mm) | B22: =IFERROR(B14-B18-B19+B20,"") -> 1298975.5
A23: Implied Equity Value — Base ($mm) | B23: =IFERROR(B15-B18-B19+B20,"") -> 1525996.1
A24: Implied Equity Value — High ($mm) | B24: =IFERROR(B16-B18-B19+B20,"") -> 2062553.3
A26: Diluted Shares Outstanding (millions) | B26: =IFERROR('Market Data'!D8,"") -> 1145
A28: Implied Share Price — Low ($) | B28: =IFERROR(IF(B22="","",B22/B26),"") -> 1134.4764
A29: Implied Share Price — Base ($) | B29: =IFERROR(IF(B23="","",B23/B26),"") -> 1332.7477
A30: Implied Share Price — High ($) | B30: =IFERROR(IF(B24="","",B24/B26),"") -> 1801.3566
A32: Current Share Price ($) | B32: =IFERROR('Market Data'!C8,"") -> 924.03
A33: Implied Upside / (Downside) — Low (%) | B33: =IFERROR(IF(B28="","",B28/B32-1),"") -> 0.2277485
A34: Implied Upside / (Downside) — Base (%) | B34: =IFERROR(IF(B29="","",B29/B32-1),"") -> 0.44232081
A35: Implied Upside / (Downside) — High (%) | B35: =IFERROR(IF(B30="","",B30/B32-1),"") -> 0.94945678
A38: Peer Tier Mapping
A39: Company | B39: Tier | C39: Rationale
A40: SK hynix Inc. | B40: Tier 1 — Direct memory | C40: DRAM + NAND; closest pure comparable. KRW; Dec year-end.
A41: Nanya Technology Corp. | B41: Tier 1 — Direct memory | C41: Commodity DRAM pure-play. TWD; Dec year-end.
A42: Kioxia Holdings Corp. | B42: Tier 1 — Direct memory | C42: NAND pure-play. JPY; Mar year-end.
A43: SanDisk Corporation | B43: Tier 1 — Direct memory | C43: NAND; spun from Western Digital 2025.
A44: Samsung Electronics Co. | B44: Tier 2 — Diversified | C44: Largest memory maker but memory is a minority of group revenue. KRW.
A45: Western Digital Corp. | B45: Tier 2 — Adjacent storage | C45: HDD post-spin; storage demand overlap, different economics.
A48: Beta & Weighted Average Cost of Capital Inputs — see WACC Build sheet
B49: MU | C49: 000660.KS | D49: 005930.KS | E49: 285A.T | F49: SNDK | G49: 2408.TW | H49: WDC
A50: Beta (5-Year Monthly vs. S&P 500) | B50: 2.25 | C50: 1.8 | D50: 1.23 | E50: 1.73 | F50: 2.6 | G50: 1.89 | H50: 2.13
A51: Fiscal Year End | B51: Aug (late) | C51: Dec 31 | D51: Dec 31 | E51: Mar 31 | F51: ~Dec | G51: Dec 31 | H51: ~Jun
A53: CALENDARIZATION REQUIRED: Micron's fiscal year ends in late August; every peer differs.
...

Sheet Current Comps (USD)
A1: Trading comparables — all figures USD, prices as of 15 September 2026
A2: Prices: LSEG USD-converted history. Fundamentals: LSEG company exports, latest reported fiscal year (period shown).
A4: Company | B4: Fundamentals period | C4: Price $ | D4: Market cap $mm | E4: EV $mm | F4: EV/Rev | G4: EV/EBITDA | H4: EV/EBIT | I4: P/E | J4: P/B | K4: GM %
A5: Micron Technology (TTM) | B5: 2026-05-28 TTM | C5: 924.03 | D5: 1058014.4 | E5: 1033536.3 | F5: 11.45 | G5: 15.14 | H5: 17.5 | I5: 20.96 | J5: 10.5 | K5: 72.56
A6: SK hynix Inc. | B6: 2025-12-31 | C6: 1254.61 | D6: 892029.13 | E6: 884455.25 | F6: 12.2 | G6: 19.4 | H6: 25.13 | I6: 27.84 | J6: 9.92 | K6: 60.37
A7: Samsung Electronics Co. | B7: 2025-12-31 | C7: 184.48 | D7: 1236569 | E7: 1161505.2 | F7: 4.67 | G7: 17.2 | H7: 35.7 | I7: 36.66 | J7: 3.91 | K7: 39.38
A8: Kioxia Holdings Corp. | B8: 2026-03-31 | C8: 335.28 | D8: 184067.06 | E8: 189110.91 | F8: 12.43 | G8: 24.6 | H8: 33.45 | I8: 51.02 | J8: 20.22 | K8: 47.15
A9: SanDisk Corporation | B9: 2026-07-03 | C9: 1530.89 | D9: 237288.73 | E9: 232526.73 | F9: 11.48 | G9: 18.43 | H9: 18.65 | I9: 20.77 | J9: 15.08 | K9: 71.47
A10: Nanya Technology Corp. | B10: 2025-12-31 | C10: 14.66 | D10: 46217.15 | E10: 45128.13 | F10: 21.44 | G10: 73.13 | H10: 272.32 | I10: 221.13 | J10: 8.58 | K10: 22.51
A11: Western Digital Corp. | B11: 2026-07-03 | C11: 411.96 | D11: 157780.68 | E11: 157253.68 | F11: 12.17 | G11: 31.62 | H11: 34.19 | I11: 16.74 | J11: 17.8 | K11: 48.85
A13: Peer median | F13: 12.19 | G13: 22 | H13: 33.82 | I13: 32.25 | J13: 12.5
A14: Peer mean | F14: 12.4 | G14: 30.73 | H14: 69.91 | I14: 62.36 | J14: 12.59
A15: Micron premium / (discount) to peer median | F15: -0.061 | G15: -0.312 | H15: -0.483 | I15: -0.35 | J15: -0.16
A17: READING: Micron trades at a DISCOUNT to the peer group on every multiple.
A18: Two qualifications. (1) Period mismatch: Micron’s denominator is TTM to 2026-05-28; SK hynix, Samsung and Nanya use CY2025 — 8.5 months stale. SK hynix needs only 28% EBITDA growth in 2026 to match Micron’s 15.1x, while Micron’s own EBITDA grew 3.7x. On a like-for-like forward basis the discount likely reverses.
A19: (2) Comps measure RELATIVE value inside a group we argue is uniformly mispriced. Our recommendation rests on absolute measures — DCF, reverse DCF, and P/B against ROE — none of which depend on Micron being dear versus Kioxia.
A21: Total return since Micron’s FY2025 close (2025-08-28) through 2026-09-15:
A22: SanDisk | B22: 2,909%
A23: Kioxia | B23: 1,893%
A24: Nanya | B24: 858%
A25: Micron | B25: 657%
A26: SK hynix | B26: 547%
A27: Western Digital | B27: 402%
A28: Samsung | B28: 267%
A29: Peer median | B29: 703%
A30: Micron sits BELOW the peer median. It is not the outlier — the sector is.

Sheet Peer Benchmark (S4)
A1: Micron vs memory peers — operating and balance-sheet benchmarks
A2: These require NO share price, so they are usable now. Source: LSEG company fundamentals exports, 2026-09-15.
A3: Period-end dates differ by company and are shown. Micron is TTM through Q3 FY2026 (2026-05-28).
A5: Company | B5: Ticker | C5: Period end | D5: Currency | E5: Revenue $mm | F5: Gross margin % | G5: EBITDA margin % | H5: Net income $mm | I5: ROE % | J5: ROIC % | K5: Current ratio | L5: Net debt / EBITDA | M5: Capex / sales %
A6: Micron Technology, Inc. | B6: MU | C6: 2026-05-28 (TTM) | D6: USD | E6: 90274 | F6: 72.57 | G6: 75.61 | H6: 50469 | I6: 65.17 | J6: 72.02 | K6: 3.42 | L6: -0.36 | M6: 27.98
A8: SK hynix Inc. | B8: 000660.KS | C8: 2025-12-31 | D8: KRW | E8: 72481.29 | F8: 60.37 | G8: 62.89 | H8: 32043.5 | I8: 44.15 | J8: 35.71 | K8: 1.86 | L8: -0.17 | M8: 29.18
A9: Samsung Electronics Co. | B9: 005930.KS | C9: 2025-12-31 | D9: KRW | E9: 248903.93 | F9: 39.38 | G9: 27.14 | H9: 33728.87 | I9: 10.85 | J9: 10.15 | K9: 2.33 | L9: -1.11 | M9: 15.58
A10: Kioxia Holdings Corp. | B10: 285A.T | C10: 2026-03-31 | D10: JPY | E10: 15208.04 | F10: 47.15 | G10: 50.56 | H10: 3607.42 | I10: 60.39 | J10: 27.59 | K10: 1.47 | L10: 0.66 | M10: 11.87
A11: SanDisk Corporation | B11: SNDK | C11: 2026-07-03 | D11: USD | E11: 20248 | F11: 71.47 | G11: 62.31 | H11: 11423 | I11: 91.56 | J11: 85.8 | K11: 2.29 | L11: -0.38 | M11: 0.87
A12: Nanya Technology Corp. | B12: 2408.TW | C12: 2025-12-31 | D12: TWD | E12: 2104.5 | F12: 22.51 | G12: 29.32 | H12: 209 | I12: 3.94 | J12: 3.65 | K12: 5.71 | L12: -1.76 | M12: 20.54
A13: Western Digital Corp. | B13: WDC | C13: 2026-07-03 | D13: USD | E13: 12919 | F13: 48.85 | G13: 38.5 | H13: 9424 | I13: 131.02 | J13: 95.02 | K13: 1.33 | L13: -0.11 | M13: 3.24
A15: Peer median | E15: 17728.02 | F15: 48 | G15: 44.53 | H15: 10423.5 | I15: 52.27 | J15: 31.65 | K15: 2.08 | L15: -0.28 | M15: 13.72
A16: Peer mean | E16: 61977.46 | F16: 48.29 | G16: 45.12 | H16: 15072.63 | I16: 56.98 | J16: 42.99 | K16: 2.5 | L16: -0.48 | M16: 13.55
A17: Peer high | E17: 248903.93 | F17: 71.47 | G17: 62.89 | H17: 33728.87 | I17: 131.02 | J17: 95.02 | K17: 5.71 | L17: 0.66 | M17: 29.18
A18: Peer low | E18: 2104.5 | F18: 22.51 | G18: 27.14 | H18: 209 | I18: 3.94 | J18: 3.65 | K18: 1.33 | L18: -1.76 | M18: 0.87
A20: Micron premium / (discount) to peer median | E20: 4.092 | F20: 0.512 | G20: 0.698 | H20: 3.842 | I20: 0.247 | J20: 1.276 | K20: 0.644 | L20: 0.286 | M20: 1.039
A22: FX (FRED, 2026-09-11): KRW 1,340.30 / JPY 153.71 / TWD 31.64 per USD.
A23: CALENDARIZATION: period ends span 2025-12-31 to 2026-07-03 against Micron TTM to 2026-05-28. Disclosed, not adjusted — these exports carry annual data only.
A24: ACCOUNTING: SK hynix, Samsung, Kioxia and Nanya report under IFRS; Micron, SanDisk and Western Digital under US GAAP.

Sheet Normalized & P-B vs ROE
A1: Micron Technology, Inc. (NASDAQ: MU)
A2: Mid-cycle multiples and the price-to-book / return-on-equity cross-check
A3: LTM multiples on a memory name at a cycle peak are close to meaningless. This sheet is the discipline.
A5: POPULATED FROM LSEG EXPORT mu.xlsx (export date 2026-09-15). MU only; peers still needed.
A7: A. Micron historical valuation multiples by fiscal year (LSEG)
A8: Fiscal year | B8: 2025 | C8: 2024 | D8: 2023 | E8: 2022 | F8: 2021 | G8: 2020 | H8: 2019
A9: Price / Book | B9: 2.53 | C9: 2.35 | D9: 1.74 | E9: 1.26 | F9: 1.88 | G9: 1.32 | H9: 1.38
A10: EV / EBITDA | B10: 7.71 | C10: 12.6 | D10: 34.98 | E10: 3.61 | F10: 6.26 | G10: 5.74 | H10: 3.76
A11: P / E diluted | B11: 16.07 | C11: 137.33 | D11: n/m | E11: 7.4 | F11: 14.4 | G11: 19.5 | H11: 8.12
A13: 7-year range | B13: P/B 1.26x - 2.53x (median 1.74x)
B14: EV/EBITDA 3.6x - 35.0x; ex-FY23-trough 3.6x - 12.6x (median 6.0x)
A16: B. Price-to-book against return on equity — the memory-sector cross-check
A17: Justified P/B = (ROE - g) / (r - g). r = 11%, g = 2.5%.
A18: Current share price ($) | B18: 924.03
A19: Current book value per share ($) | B19: 89.22
A20: Current P/B (x) | B20: =B18/B19 -> 10.356759
A21: Current TTM ROE (%) | B21: 65.17
A23: Sustained ROE | B23: Justified P/B | C23: Implied price | D23: vs market
A24: 0.15 | B24: =(A24-0.025)/(0.11-0.025) -> 1.4705882 | C24: =B24*$B$19 -> 131.20588 | D24: =C24/$B$18-1 -> -0.8580069
A25: 0.2 | B25: =(A25-0.025)/(0.11-0.025) -> 2.0588235 | C25: =B25*$B$19 -> 183.68824 | D25: =C25/$B$18-1 -> -0.80120966
A26: 0.25 | B26: =(A26-0.025)/(0.11-0.025) -> 2.6470588 | C26: =B26*$B$19 -> 236.17059 | D26: =C26/$B$18-1 -> -0.74441242
A27: 0.3 | B27: =(A27-0.025)/(0.11-0.025) -> 3.2352941 | C27: =B27*$B$19 -> 288.65294 | D27: =C27/$B$18-1 -> -0.68761518
A28: 0.4 | B28: =(A28-0.025)/(0.11-0.025) -> 4.4117647 | C28: =B28*$B$19 -> 393.61765 | D28: =C28/$B$18-1 -> -0.57402071
A29: 0.5 | B29: =(A29-0.025)/(0.11-0.025) -> 5.5882353 | C29: =B29*$B$19 -> 498.58235 | D29: =C29/$B$18-1 -> -0.46042623
A30: 0.65 | B30: =(A30-0.025)/(0.11-0.025) -> 7.3529412 | C30: =B30*$B$19 -> 656.02941 | D30: =C30/$B$18-1 -> -0.29003451
A32: ROE required to justify the current price | B32: 0.905
A33: FY21-FY25 mean ROE 7.7%; prior-cycle peak 18.5% (FY2022). The market requires ~4.9x the best prior-cycle year, permanently.
A35: C. Triangulation — every method against the $924 price
A36: Scenario DCF, probability-weighted 25/50/25 | B36: 532 | C36: =B36/924.03-1 -> -0.42426112
A37: P/B at 7-year median 1.74x on current BVPS | B37: 155 | C37: =B37/924.03-1 -> -0.83225653
A38: P/B at 7-year maximum 2.53x on current BVPS | B38: 226 | C38: =B38/924.03-1 -> -0.7554192
A39: P/B justified by a normalized 20% ROE | B39: 184 | C39: =B39/924.03-1 -> -0.80087227
A40: P/B justified by a normalized 30% ROE | B40: 289 | C40: =B40/924.03-1 -> -0.68723959
A41: EV/EBITDA at 6.0x ex-trough median on mid-cycle EBITDA $45B | B41: 257 | C41: =B41/924.03-1 -> -0.7218705
A42: Asset / replacement-cost floor (proxy) | B42: 131 | C42: =B42/924.03-1 -> -0.85822971
A44: CAVEAT — read before using
A45: SUPERSEDED — see section D below for the forward-book resolution.
A47: D. RESOLVING THE P/B vs DCF DIVERGENCE — forward book value
A48: Current-book P/B gave $155-$289 against a DCF of $406. The gap is a timing mismatch: Micron retains ~94% of earnings, so book compounds fast. Rolling book forward on the base-case earnings path and applying the SAME historical multiples is the like-for-like comparison.
A50: Book value per share, FY2031E (base case) | B50: 437
...

Sheet WACC Build
A1: Micron Technology, Inc. — Weighted Average Cost of Capital
A2: Structure lifted from last cycle's DCF template. Replaces the 11% assumed rate in the model.
A4: INPUTS
A5: Risk-free rate — US 10Y Treasury | B5: 0.0497 | C5: FRED DGS10, 2026-09-14
A6: Equity risk premium | B6: 0.05 | C6: Assumption. Sensitised below.
A7: Pre-tax cost of debt | B7: 0.059 | C7: FRED BAMLC0A4CBBBEY, ICE BofA BBB index, 2026-09-14
A8: Marginal tax rate | B8: 0.15 | C8: FY26 effective rate 14.6%
A9: Market value of equity ($mm) | B9: 1058014.4 | C9: $924.03 x 1,145M diluted
A10: Total debt ($mm) | B10: 5722 | C10: Q3 FY26 10-Q, debt and capital leases
A12: BETA — the choice that decides the answer
A13: MU raw 5-yr monthly beta | B13: 2.25 | C13: LSEG
A14: MU Blume-adjusted (0.67b + 0.33) | B14: =0.67*B13+0.33 -> 1.8375 | C14: Standard correction for beta reversion toward 1.0
A15: Peer median raw beta | B15: 1.84 | C15: SK hynix 1.80, Samsung 1.23, Kioxia 1.73, SanDisk 2.60, Nanya 1.89, WDC 2.13
A16: SELECTED BETA | B16: =B14 -> 1.8375 | C16: Blume-adjusted. Corroborated independently by the peer median of 1.84.
A18: BUILD
A19: Cost of equity | B19: =B5+B16*B6 -> 0.141575
A20: After-tax cost of debt | B20: =B7*(1-B8) -> 0.05015
A21: Equity weight | B21: =B9/(B9+B10) -> 0.99462085
A22: Debt weight | B22: =B10/(B9+B10) -> 0.0053791525
A23: WACC | B23: =B19*B21+B20*B22 -> 0.14108321 | C23: Micron is ~99.5% equity-funded, so WACC is essentially cost of equity
A25: SENSITIVITY — WACC by beta treatment
A26: Raw beta 2.25 | B26: =B5+2.25*B6 -> 0.1622
A27: Blume-adjusted 1.84 | B27: =B5+1.84*B6 -> 0.1417
A28: Peer median Blume-adjusted 1.56 | B28: =B5+1.56*B6 -> 0.1277
A29: Originally assumed in the model | B29: 0.11
A31: Formula audit 16 Sep: B14 and B23 were circular; B16 pointed at the peer median rather than the Blume figure; B19 referenced a blank cell. All four corrected.
A32: Base WACC | B32: Source | C32: Bull | D32: Base | E32: Bear | F32: Weighted 25/50/25 | G32: vs $924
A33: 0.11 | B33: originally assumed | C33: 1049 | D33: 453 | E33: 173 | F33: 532 | G33: -0.42
A34: 0.1274 | B34: peer median, Blume-adjusted | C34: 862 | D34: 392 | E34: 162 | F34: 452 | G34: -0.51
A35: 0.1411 | B35: MU beta, Blume-adjusted (SELECTED) | C35: 758 | D35: 357 | E35: 154 | F35: 406 | G35: -0.56
A36: 0.1616 | B36: MU raw 5-yr beta | C36: 643 | D36: 316 | E36: 145 | F36: 355 | G36: -0.62
A38: NOTE ON BIAS: a higher WACC strengthens our Sell case. We adopt the Blume-adjusted beta, not the raw one, precisely because the raw figure is inflated by the 2026 upcycle we argue is temporary — applying peak-volatility beta to normalized cash flows is internally inconsistent, and choosing the input that most flatters our own conclusion is an opening a judge should take.
