Workbook

Sheet Assumptions
A1: Micron Technology, Inc. (NASDAQ: MU)
A2: Scenario Discounted Cash Flow — contracted / spot tranche decomposition
A3: Market data as of 15 Sep 2026. Financials from SEC 10-K/10-Q; FY2026 Q4 at management guidance (8-K 24 Jun 2026).
A4: YELLOW = input. GREEN = calculated. Change B7 to switch scenario.
A6: SCENARIO SWITCH
A7: Active scenario (1=Bull, 2=Base, 3=Bear) | B7: 1 | C7: =IF(B7=1,"BULL",IF(B7=2,"BASE","BEAR")) -> BULL
A9: COST OF CAPITAL
A10: Risk-free rate (US 10Y Treasury) | B10: 0.0497 | C10: FRED DGS10, 14 Sep 2026
A11: Equity risk premium | B11: 0.05 | C11: Assumption
A12: Levered beta — raw 5-yr monthly | B12: 2.25 | C12: LSEG
A13: Levered beta — Blume-adjusted (SELECTED) | B13: =0.67*B12+0.33 -> 1.8375 | C13: Peer median raw beta is also 1.84
A14: Cost of equity | B14: =B10+B13*B11 -> 0.141575
A15: Pre-tax cost of debt | B15: 0.059 | C15: FRED BAMLC0A4CBBBEY, ICE BofA BBB
A16: Marginal tax rate | B16: 0.15 | C16: FY26 effective rate 14.6%
A17: After-tax cost of debt | B17: =B15*(1-B16) -> 0.05015
A18: Market value of equity ($mm) | B18: =B34*B35 -> 1058014.3 | C18: price x diluted shares
A19: Total debt ($mm) | B19: 5722 | C19: Q3 FY26 10-Q
A20: Equity weight | B20: =B18/(B18+B19) -> 0.99462085
A21: Debt weight | B21: =B19/(B18+B19) -> 0.0053791525
A22: WACC — base | B22: =B14*B20+B17*B21 -> 0.14108321
A24: Scenario WACC spread (bp vs base)
B25: Bull | C25: Base | D25: Bear
A26: spread (bp) | B26: -50 | C26: 0 | D26: 100
A27: Active WACC | B27: =$B$22+INDEX(B26:D26,1,$B$7)/10000 -> 0.13608321
A29: Terminal growth rate | B29: 0.03 | C29: 0.025 | D29: 0.02
A30: Active terminal growth | B30: =INDEX(B29:D29,1,$B$7) -> 0.03
A32: MARKET DATA
A34: Share price ($) | B34: 924.03 | C34: LSEG, 15 Sep 2026
A35: Diluted shares (mm) | B35: 1145 | C35: Q3 FY26 10-Q
A36: Cash, marketable & restricted ($mm) | B36: 30200 | C36: Q3 FY26 earnings release
A37: Net cash ($mm) | B37: =B36-B19 -> 24478
A38: Gross PP&E ($mm) | B38: 124991 | C38: Q3 FY26 10-Q; asset-floor proxy
A40: FORECAST DRIVERS — by scenario
A41: FY2027 and FY2028 are LSEG I/B/E/S MEAN CONSENSUS in all three scenarios (retrieved 15 Sep 2026) - sourced, not modelled.
A42: The scenarios differ only in the FY2029-FY2031 reversion path. That isolates the disagreement to the years consensus does not reach.
B44: FY2027E | C44: FY2028E | D44: FY2029E | E44: FY2030E | F44: FY2031E
A45: Revenue ($B)
A46: Bull | B46: 248.757 | C46: 289.72 | D46: 270 | E46: 250 | F46: 240
A47: Base | B47: 248.757 | C47: 289.72 | D47: 210 | E47: 165 | F47: 150
A48: Bear | B48: 248.757 | C48: 289.72 | D48: 180 | E48: 120 | F48: 100
...

Sheet Unlevered FCF
A1: Unlevered Free Cash Flow Build ($mm unless noted)
A2: =Assumptions!C7&" scenario" -> BULL scenario
B4: FY2027E | C4: FY2028E | D4: FY2029E | E4: FY2030E | F4: FY2031E
A5: Revenue | B5: =Assumptions!B49*1000 -> 248757 | C5: =Assumptions!C49*1000 -> 289720 | D5: =Assumptions!D49*1000 -> 270000 | E5: =Assumptions!E49*1000 -> 250000 | F5: =Assumptions!F49*1000 -> 240000
A6: Revenue growth | B6: =IF(A5=0,"",B5/A5-1) -> #VALUE! | C6: =IF(B5=0,"",C5/B5-1) -> 0.16467074 | D6: =IF(C5=0,"",D5/C5-1) -> -0.068065719 | E6: =IF(D5=0,"",E5/D5-1) -> -0.074074074 | F6: =IF(E5=0,"",F5/E5-1) -> -0.04
A7: Blended gross margin | B7: =Assumptions!B55 -> 0.85 | C7: =Assumptions!C55 -> 0.82 | D7: =Assumptions!D55 -> 0.72 | E7: =Assumptions!E55 -> 0.65 | F7: =Assumptions!F55 -> 0.6
A8: Gross profit | B8: =B5*B7 -> 211443.45 | C8: =C5*C7 -> 237570.4 | D8: =D5*D7 -> 194400 | E8: =E5*E7 -> 162500 | F8: =F5*F7 -> 144000
A9: Operating expenses | B9: =-B5*Assumptions!$B$63 -> -6218.925 | C9: =-C5*Assumptions!$B$63 -> -7243 | D9: =-D5*Assumptions!$B$63 -> -6750 | E9: =-E5*Assumptions!$B$63 -> -6250 | F9: =-F5*Assumptions!$B$63 -> -6000
A10: EBIT | B10: =B8+B9 -> 205224.52 | C10: =C8+C9 -> 230327.4 | D10: =D8+D9 -> 187650 | E10: =E8+E9 -> 156250 | F10: =F8+F9 -> 138000
A11: EBIT margin | B11: =B10/B5 -> 0.825 | C11: =C10/C5 -> 0.795 | D11: =D10/D5 -> 0.695 | E11: =E10/E5 -> 0.625 | F11: =F10/F5 -> 0.575
A12: Less: cash taxes on EBIT | B12: =-B10*Assumptions!$B$65 -> -30783.679 | C12: =-C10*Assumptions!$B$65 -> -34549.11 | D12: =-D10*Assumptions!$B$65 -> -28147.5 | E12: =-E10*Assumptions!$B$65 -> -23437.5 | F12: =-F10*Assumptions!$B$65 -> -20700
A13: NOPAT | B13: =B10+B12 -> 174440.85 | C13: =C10+C12 -> 195778.29 | D13: =D10+D12 -> 159502.5 | E13: =E10+E12 -> 132812.5 | F13: =F10+F12 -> 117300
A14: Plus: D&A | B14: =B5*Assumptions!$B$64 -> 23631.915 | C14: =C5*Assumptions!$B$64 -> 27523.4 | D14: =D5*Assumptions!$B$64 -> 25650 | E14: =E5*Assumptions!$B$64 -> 23750 | F14: =F5*Assumptions!$B$64 -> 22800
A15: Less: capital expenditure | B15: =-B5*Assumptions!B61 -> -54726.54 | C15: =-C5*Assumptions!C61 -> -57944 | D15: =-D5*Assumptions!D61 -> -48600 | E15: =-E5*Assumptions!E61 -> -40000 | F15: =-F5*Assumptions!F61 -> -36000
A16: Unlevered free cash flow | B16: =B13+B14+B15 -> 143346.22 | C16: =C13+C14+C15 -> 165357.69 | D16: =D13+D14+D15 -> 136552.5 | E16: =E13+E14+E15 -> 116562.5 | F16: =F13+F14+F15 -> 104100
A17: UFCF margin | B17: =B16/B5 -> 0.57625 | C17: =C16/C5 -> 0.57075 | D17: =D16/D5 -> 0.50575 | E17: =E16/E5 -> 0.46625 | F17: =F16/F5 -> 0.43375
A18: Discount period | B18: 1 | C18: 2 | D18: 3 | E18: 4 | F18: 5
A19: Discount factor | B19: =1/(1+Assumptions!$B$27)^B18 -> 0.88021722 | C19: =1/(1+Assumptions!$B$27)^C18 -> 0.77478235 | D19: =1/(1+Assumptions!$B$27)^D18 -> 0.68197676 | E19: =1/(1+Assumptions!$B$27)^E18 -> 0.60028768 | F19: =1/(1+Assumptions!$B$27)^F18 -> 0.52838355
A20: PV of UFCF | B20: =B16*B19 -> 126175.81 | C20: =C16*C19 -> 128116.22 | D20: =D16*D19 -> 93125.631 | E20: =E16*E19 -> 69971.033 | F20: =F16*F19 -> 55004.728

Sheet DCF Valuation
A1: DCF Valuation Summary
A2: =Assumptions!C7&" scenario" -> BULL scenario
A4: Sum of PV of explicit-period UFCF | B4: =SUM('Unlevered FCF'!B20:F20) -> 472393.42
A5: Terminal year UFCF | B5: ='Unlevered FCF'!F16 -> 104100
A6: Terminal growth | B6: =Assumptions!B30 -> 0.03
A7: WACC | B7: =Assumptions!B27 -> 0.13608321
A8: Terminal value (Gordon growth) | B8: =B5*(1+B6)/(B7-B6) -> 1010744.3
A9: PV of terminal value | B9: =B8/(1+B7)^5 -> 534060.66
A10: Enterprise value | B10: =B4+B9 -> 1006454.1
A11: Terminal value as % of EV | B11: =B9/B10 -> 0.53063589 | C11: PASS if under 75%; above that the model is a perpetuity assumption wearing a spreadsheet
A12: Plus: net cash | B12: =Assumptions!B37 -> 24478
A13: Equity value | B13: =B10+B12 -> 1030932.1
A14: Diluted shares (mm) | B14: =Assumptions!B35 -> 1145
A15: Implied value per share | B15: =B13/B14 -> 900.37736
A16: Asset / replacement-cost floor per share | B16: =(Assumptions!B38+Assumptions!B37)/Assumptions!B35 -> 130.54061 | C16: Gross PP&E at historical cost plus net cash. Conservative: fab replacement cost exceeds book.
A17: Value per share after floor | B17: =MAX(B15,B16) -> 900.37736
A18: Current share price | B18: =Assumptions!B34 -> 924.03
A19: Implied upside / (downside) | B19: =B17/B18-1 -> -0.025597259
A22: SENSITIVITY — value per share: WACC against terminal growth
B24: 0.015 | C24: 0.02 | D24: 0.025 | E24: 0.03 | F24: 0.035
A25: 0.121 | B25: =(SUM('Unlevered FCF'!$B$16:$F$16)*0+(('Unlevered FCF'!$F$16*(1+0.015)/(0.121-0.015))/(1+0.121)^5+SUMPRODUCT('Unlevered FCF'!$B$16:$F$16,1/(1+0.121)^{1,2,3,4,5}))+Assumptions!$B$37)/Assumptions!$B$35 -> 940.25357 | C25: =(SUM('Unlevered FCF'!$B$16:$F$16)*0+(('Unlevered FCF'!$F$16*(1+0.02)/(0.121-0.02))/(1+0.121)^5+SUMPRODUCT('Unlevered FCF'!$B$16:$F$16,1/(1+0.121)^{1,2,3,4,5}))+Assumptions!$B$37)/Assumptions!$B$35 -> 967.142 | D25: =(SUM('Unlevered FCF'!$B$16:$F$16)*0+(('Unlevered FCF'!$F$16*(1+0.025)/(0.121-0.025))/(1+0.121)^5+SUMPRODUCT('Unlevered FCF'!$B$16:$F$16,1/(1+0.121)^{1,2,3,4,5}))+Assumptions!$B$37)/Assumptions!$B$35 -> 996.83132 | E25: =(SUM('Unlevered FCF'!$B$16:$F$16)*0+(('Unlevered FCF'!$F$16*(1+0.03)/(0.121-0.03))/(1+0.121)^5+SUMPRODUCT('Unlevered FCF'!$B$16:$F$16,1/(1+0.121)^{1,2,3,4,5}))+Assumptions!$B$37)/Assumptions!$B$35 -> 1029.7832 | F25: =(SUM('Unlevered FCF'!$B$16:$F$16)*0+(('Unlevered FCF'!$F$16*(1+0.035)/(0.121-0.035))/(1+0.121)^5+SUMPRODUCT('Unlevered FCF'!$B$16:$F$16,1/(1+0.121)^{1,2,3,4,5}))+Assumptions!$B$37)/Assumptions!$B$35 -> 1066.5667
A26: 0.131 | B26: =(SUM('Unlevered FCF'!$B$16:$F$16)*0+(('Unlevered FCF'!$F$16*(1+0.015)/(0.131-0.015))/(1+0.131)^5+SUMPRODUCT('Unlevered FCF'!$B$16:$F$16,1/(1+0.131)^{1,2,3,4,5}))+Assumptions!$B$37)/Assumptions!$B$35 -> 868.62217 | C26: =(SUM('Unlevered FCF'!$B$16:$F$16)*0+(('Unlevered FCF'!$F$16*(1+0.02)/(0.131-0.02))/(1+0.131)^5+SUMPRODUCT('Unlevered FCF'!$B$16:$F$16,1/(1+0.131)^{1,2,3,4,5}))+Assumptions!$B$37)/Assumptions!$B$35 -> 890.19881 | D26: =(SUM('Unlevered FCF'!$B$16:$F$16)*0+(('Unlevered FCF'!$F$16*(1+0.025)/(0.131-0.025))/(1+0.131)^5+SUMPRODUCT('Unlevered FCF'!$B$16:$F$16,1/(1+0.131)^{1,2,3,4,5}))+Assumptions!$B$37)/Assumptions!$B$35 -> 913.81099 | E26: =(SUM('Unlevered FCF'!$B$16:$F$16)*0+(('Unlevered FCF'!$F$16*(1+0.03)/(0.131-0.03))/(1+0.131)^5+SUMPRODUCT('Unlevered FCF'!$B$16:$F$16,1/(1+0.131)^{1,2,3,4,5}))+Assumptions!$B$37)/Assumptions!$B$35 -> 939.761 | F26: =(SUM('Unlevered FCF'!$B$16:$F$16)*0+(('Unlevered FCF'!$F$16*(1+0.035)/(0.131-0.035))/(1+0.131)^5+SUMPRODUCT('Unlevered FCF'!$B$16:$F$16,1/(1+0.131)^{1,2,3,4,5}))+Assumptions!$B$37)/Assumptions!$B$35 -> 968.41414
A27: 0.141 | B27: =(SUM('Unlevered FCF'!$B$16:$F$16)*0+(('Unlevered FCF'!$F$16*(1+0.015)/(0.141-0.015))/(1+0.141)^5+SUMPRODUCT('Unlevered FCF'!$B$16:$F$16,1/(1+0.141)^{1,2,3,4,5}))+Assumptions!$B$37)/Assumptions!$B$35 -> 808.10712 | C27: =(SUM('Unlevered FCF'!$B$16:$F$16)*0+(('Unlevered FCF'!$F$16*(1+0.02)/(0.141-0.02))/(1+0.141)^5+SUMPRODUCT('Unlevered FCF'!$B$16:$F$16,1/(1+0.141)^{1,2,3,4,5}))+Assumptions!$B$37)/Assumptions!$B$35 -> 825.69918 | D27: =(SUM('Unlevered FCF'!$B$16:$F$16)*0+(('Unlevered FCF'!$F$16*(1+0.025)/(0.141-0.025))/(1+0.141)^5+SUMPRODUCT('Unlevered FCF'!$B$16:$F$16,1/(1+0.141)^{1,2,3,4,5}))+Assumptions!$B$37)/Assumptions!$B$35 -> 844.8078 | E27: =(SUM('Unlevered FCF'!$B$16:$F$16)*0+(('Unlevered FCF'!$F$16*(1+0.03)/(0.141-0.03))/(1+0.141)^5+SUMPRODUCT('Unlevered FCF'!$B$16:$F$16,1/(1+0.141)^{1,2,3,4,5}))+Assumptions!$B$37)/Assumptions!$B$35 -> 865.63791 | F27: =(SUM('Unlevered FCF'!$B$16:$F$16)*0+(('Unlevered FCF'!$F$16*(1+0.035)/(0.141-0.035))/(1+0.141)^5+SUMPRODUCT('Unlevered FCF'!$B$16:$F$16,1/(1+0.141)^{1,2,3,4,5}))+Assumptions!$B$37)/Assumptions!$B$35 -> 888.43314
A28: 0.151 | B28: =(SUM('Unlevered FCF'!$B$16:$F$16)*0+(('Unlevered FCF'!$F$16*(1+0.015)/(0.151-0.015))/(1+0.151)^5+SUMPRODUCT('Unlevered FCF'!$B$16:$F$16,1/(1+0.151)^{1,2,3,4,5}))+Assumptions!$B$37)/Assumptions!$B$35 -> 756.2668 | C28: =(SUM('Unlevered FCF'!$B$16:$F$16)*0+(('Unlevered FCF'!$F$16*(1+0.02)/(0.151-0.02))/(1+0.151)^5+SUMPRODUCT('Unlevered FCF'!$B$16:$F$16,1/(1+0.151)^{1,2,3,4,5}))+Assumptions!$B$37)/Assumptions!$B$35 -> 770.80477 | D28: =(SUM('Unlevered FCF'!$B$16:$F$16)*0+(('Unlevered FCF'!$F$16*(1+0.025)/(0.151-0.025))/(1+0.151)^5+SUMPRODUCT('Unlevered FCF'!$B$16:$F$16,1/(1+0.151)^{1,2,3,4,5}))+Assumptions!$B$37)/Assumptions!$B$35 -> 786.49655 | E28: =(SUM('Unlevered FCF'!$B$16:$F$16)*0+(('Unlevered FCF'!$F$16*(1+0.03)/(0.151-0.03))/(1+0.151)^5+SUMPRODUCT('Unlevered FCF'!$B$16:$F$16,1/(1+0.151)^{1,2,3,4,5}))+Assumptions!$B$37)/Assumptions!$B$35 -> 803.48516 | F28: =(SUM('Unlevered FCF'!$B$16:$F$16)*0+(('Unlevered FCF'!$F$16*(1+0.035)/(0.151-0.035))/(1+0.151)^5+SUMPRODUCT('Unlevered FCF'!$B$16:$F$16,1/(1+0.151)^{1,2,3,4,5}))+Assumptions!$B$37)/Assumptions!$B$35 -> 821.93832
A29: 0.161 | B29: =(SUM('Unlevered FCF'!$B$16:$F$16)*0+(('Unlevered FCF'!$F$16*(1+0.015)/(0.161-0.015))/(1+0.161)^5+SUMPRODUCT('Unlevered FCF'!$B$16:$F$16,1/(1+0.161)^{1,2,3,4,5}))+Assumptions!$B$37)/Assumptions!$B$35 -> 711.32803 | C29: =(SUM('Unlevered FCF'!$B$16:$F$16)*0+(('Unlevered FCF'!$F$16*(1+0.02)/(0.161-0.02))/(1+0.161)^5+SUMPRODUCT('Unlevered FCF'!$B$16:$F$16,1/(1+0.161)^{1,2,3,4,5}))+Assumptions!$B$37)/Assumptions!$B$35 -> 723.4819 | D29: =(SUM('Unlevered FCF'!$B$16:$F$16)*0+(('Unlevered FCF'!$F$16*(1+0.025)/(0.161-0.025))/(1+0.161)^5+SUMPRODUCT('Unlevered FCF'!$B$16:$F$16,1/(1+0.161)^{1,2,3,4,5}))+Assumptions!$B$37)/Assumptions!$B$35 -> 736.52943 | E29: =(SUM('Unlevered FCF'!$B$16:$F$16)*0+(('Unlevered FCF'!$F$16*(1+0.03)/(0.161-0.03))/(1+0.161)^5+SUMPRODUCT('Unlevered FCF'!$B$16:$F$16,1/(1+0.161)^{1,2,3,4,5}))+Assumptions!$B$37)/Assumptions!$B$35 -> 750.57295 | F29: =(SUM('Unlevered FCF'!$B$16:$F$16)*0+(('Unlevered FCF'!$F$16*(1+0.035)/(0.161-0.035))/(1+0.161)^5+SUMPRODUCT('Unlevered FCF'!$B$16:$F$16,1/(1+0.161)^{1,2,3,4,5}))+Assumptions!$B$37)/Assumptions!$B$35 -> 765.73105
A31: Rows = WACC, columns = terminal growth.

Sheet Scenario Summary
A1: Scenario Summary and Probability-Weighted Target
A2: Values below are hard-coded from running each scenario. Re-run Assumptions!B7 = 1, 2, 3 and paste DCF Valuation!B17 to refresh.
A4: Scenario | B4: FY27 rev $B | C4: FY31 rev $B | D4: FY31 GM | E4: WACC | F4: TV % of EV | G4: Value / share | H4: Probability | I4: Weighted
A5: Bull — consensus holds, reversion shallow and late | B5: 248.8 | C5: 240 | D5: 0.6 | E5: 0.136 | F5: 0.53 | G5: 900 | H5: 0.25 | I5: =G5*H5 -> 225
A6: Base — consensus through FY2028, then the cycle turns | B6: 248.8 | C6: 150 | D6: 0.42 | E6: 0.141 | F6: 0.35 | G6: 497 | H6: 0.5 | I6: =G6*H6 -> 248.5
A7: Bear — consensus through FY2028, then Chinese supply lands | B7: 248.8 | C7: 100 | D7: 0.25 | E7: 0.151 | F7: 0.13 | G7: 299 | H7: 0.25 | I7: =G7*H7 -> 74.75
A9: Probability-weighted target | H9: =SUM(H5:H7) -> 1 | I9: =SUM(I5:I7) -> 548.25
A10: Current price | I10: =Assumptions!B34 -> 924.03
A11: Implied upside / (downside) | I11: =I9/I10-1 -> -0.40667511
A13: FY2027-28 are consensus in all three cases. The bull case ($900) sits only 3% below the market price:
A14: if the cycle does not reassert after FY2028, Micron is roughly fairly valued. The recommendation rests entirely on the probability that it does.

Sheet Reverse DCF
A1: Reverse DCF — what must be true at $924.03?
A2: Solves the model backwards: what sustained revenue and terminal gross margin does the current price require?
A4: WACC 14.1%, terminal growth 2.5%, capex converging to 12.5% of sales. Compare against consensus: FY2027 $249B at 85%, FY2028 $290B at 82%.
A6: Terminal revenue | B6: 0.35 | C6: 0.45 | D6: 0.55 | E6: 0.65 | F6: 0.7 | G6: 0.75
A7: $100B | B7: 288 | C7: 335 | D7: 382 | E7: 429 | F7: 452 | G7: 476
A8: $120B | B8: 316 | C8: 371 | D8: 426 | E8: 482 | F8: 509 | G8: 537
A9: $140B | B9: 343 | C9: 407 | D9: 471 | E9: 535 | F9: 567 | G9: 598
A10: $160B | B10: 371 | C10: 443 | D10: 515 | E10: 588 | F10: 624 | G10: 660
A11: $180B | B11: 399 | C11: 480 | D11: 560 | E11: 640 | F11: 681 | G11: 721
A12: $200B | B12: 427 | C12: 516 | D12: 605 | E12: 693 | F12: 738 | G12: 782
A14: Terminal gross margin required to justify $924.03
A15: Sustained revenue | B15: Required terminal GM
A16: $140B | B16: 126% | C16: exceeds any gross margin ever recorded in memory
A17: $160B | B17: 112% | C17: exceeds any gross margin ever recorded in memory
A18: $180B | B18: 100% | C18: exceeds any gross margin ever recorded in memory
A19: $200B | B19: 91% | C19: exceeds any gross margin ever recorded in memory
A20: $240B | B20: 77%
A22: Micron's five-year mean gross margin is 27.2%; its highest ever is the ~86% guided for Q4 FY2026.
A23: The first combination that is even theoretically achievable is $240B of revenue at 77% GM, in perpetuity.
A25: CONSENSUS CONTEXT: LSEG I/B/E/S projects $249B at 85% (FY27) and $290B at 82% (FY28), which EXCEEDS
A26: the level the current price requires. The market is not pricing beyond consensus - it is pricing at it.
A27: The recommendation is therefore a disagreement with consensus about FY2029 onward, not about the price.
