Workbook

Sheet Assumptions
A1: Oracle Corporation (NYSE: ORCL)
A2: Two-Stage Unlevered Discounted Cash Flow Model — Key Assumptions
A3: Sources: SEC EDGAR 10-K/10-Q filings, LSEG, StockAnalysis.com, analyst consensus
B5: FY2023A | C5: FY2024A | D5: FY2025A | E5: FY2026E | F5: FY2027E | G5: FY2028E | H5: FY2029E | I5: FY2030E | J5: Source / Notes
A7: Revenue Assumptions
A8: Total Revenue ($mm) | B8: 49954 | C8: 52961 | D8: 57399 | E8: 68300 | F8: 88400 | G8: 106100 | H8: 122000 | I8: 136600 | J8: Source: FY23-25 Oracle 10-K; FY26-27 consensus; FY28-30 model est.
A9: Revenue Growth (%) | C9: =C8/B8-1 -> 0.06019538 | D9: =D8/C8-1 -> 0.083797511 | E9: =E8/D8-1 -> 0.1899162 | F9: =F8/E8-1 -> 0.2942899 | G9: =G8/F8-1 -> 0.20022624 | H9: =H8/G8-1 -> 0.14985862 | I9: =I8/H8-1 -> 0.11967213
A11: EBITDA & Operating Assumptions
A12: EBITDA ($mm) | B12: =B8*B13 -> 19167.35 | C12: =C8*C13 -> 21459.797 | D12: =D8*D13 -> 23849.284 | E12: =E8*E13 -> 28686 | F12: =F8*F13 -> 38012 | G12: =G8*G13 -> 46684 | H12: =H8*H13 -> 54900 | I12: =I8*I13 -> 61470
A13: EBITDA Margin (%) | B13: 0.3837 | C13: 0.4052 | D13: 0.4155 | E13: 0.42 | F13: 0.43 | G13: 0.44 | H13: 0.45 | I13: 0.45 | J13: Margin expansion driven by cloud mix shift and OCI operating leverage
A14: Depreciation & Amortization ($mm) | B14: 6108 | C14: 6089 | D14: 6174 | E14: 9000 | F14: 13000 | G14: 16000 | H14: 18000 | I14: 19500 | J14: Rising D&A reflects cumulative AI/OCI capex entering service (15-20yr lives)
A15: D&A as % of Revenue | B15: =B14/B8 -> 0.12227249 | C15: =C14/C8 -> 0.11497139 | D15: =D14/D8 -> 0.10756285 | E15: =E14/E8 -> 0.1317716 | F15: =F14/F8 -> 0.14705882 | G15: =G14/G8 -> 0.15080113 | H15: =H14/H8 -> 0.14754098 | I15: =I14/I8 -> 0.14275256
A16: EBIT (Operating Income) ($mm) | B16: =B12-B14 -> 13059.35 | C16: =C12-C14 -> 15370.797 | D16: =D12-D14 -> 17675.284 | E16: =E12-E14 -> 19686 | F16: =F12-F14 -> 25012 | G16: =G12-G14 -> 30684 | H16: =H12-H14 -> 36900 | I16: =I12-I14 -> 41970
A17: EBIT Margin (%) | B17: =B16/B8 -> 0.26142751 | C17: =C16/C8 -> 0.29022861 | D17: =D16/D8 -> 0.30793715 | E17: =E16/E8 -> 0.2882284 | F17: =F16/F8 -> 0.28294118 | G17: =G16/G8 -> 0.28919887 | H17: =H16/H8 -> 0.30245902 | I17: =I16/I8 -> 0.30724744
A19: Capital Expenditure & Working Capital Assumptions
A20: Capital Expenditures ($mm) | B20: 8695 | C20: 6866 | D20: 21194 | E20: 42000 | F20: 38000 | G20: 30000 | H20: 25000 | I20: 22000 | J20: Source: FY23-25 SEC filings; FY26E reflects ~$48B trailing run rate; normalizes by FY30
A21: CapEx as % of Revenue | B21: =B20/B8 -> 0.17406014 | C21: =C20/C8 -> 0.12964257 | D21: =D20/D8 -> 0.36923988 | E21: =E20/E8 -> 0.61493411 | F21: =F20/F8 -> 0.42986425 | G21: =G20/G8 -> 0.28275212 | H21: =H20/H8 -> 0.20491803 | I21: =I20/I8 -> 0.16105417
A22: Change in Net Working Capital ($mm) | B22: 800 | C22: 600 | D22: 700 | E22: 163 | F22: 302 | G22: 266 | H22: 239 | I22: 219 | J22: Estimated at ~1.5% of annual revenue change
A23: NWC Change as % of Revenue Change | C23: =IF(C8-B8=0,0,C22/(C8-B8)) -> 0.19953442 | D23: =IF(D8-C8=0,0,D22/(D8-C8)) -> 0.15772871 | E23: =IF(E8-D8=0,0,E22/(E8-D8)) -> 0.014952757 | F23: =IF(F8-E8=0,0,F22/(F8-E8)) -> 0.015024876 | G23: =IF(G8-F8=0,0,G22/(G8-F8)) -> 0.015028249 | H23: =IF(H8-G8=0,0,H22/(H8-G8)) -> 0.015031447 | I23: =IF(I8-H8=0,0,I22/(I8-H8)) -> 0.015
A24: Effective Tax Rate on EBIT (%) | B24: 0.15 | C24: 0.149 | D24: 0.136 | E24: 0.19 | F24: 0.19 | G24: 0.19 | H24: 0.19 | I24: 0.19 | J24: Normalized to 19.0% for projections (historical Oracle avg ~15-20%)
A26: Weighted Average Cost of Capital Assumptions
A27: Risk-Free Rate (%) | B27: 0.043 | J27: Source: U.S. 10-Year Treasury yield, March 2026
A28: Equity Risk Premium (%) | B28: 0.055 | J28: Source: Damodaran January 2026 implied ERP
A29: Levered Beta | B29: 1.4 | J29: Source: LSEG — 5-year monthly vs. S&P 500
A30: Unlevered Beta | B30: =B29/(1+(1-B34)*(B38/B37)) -> 1.1932031 | J30: Hamada: Bu = Bl / (1 + (1-t)*D/E)
A31: Cost of Equity (%) | B31: =B27+B29*B28 -> 0.12 | J31: CAPM: Ke = Rf + Beta * ERP
A33: Pre-Tax Cost of Debt (%) | B33: 0.045 | J33: Weighted avg coupon on Oracle outstanding senior notes
A34: Marginal Tax Rate (%) | B34: 0.19 | J34: Consistent with projection tax rate assumption
A35: After-Tax Cost of Debt (%) | B35: =B33*(1-B34) -> 0.03645 | J35: Kd * (1 - Tax Rate)
A37: Market Value of Equity ($mm) | B37: 446342 | J37: Source: LSEG — Price $155.52 x 2,870mm diluted shares
A38: Total Debt ($mm) | B38: 95502 | J38: Source: Oracle FY2025 10-K balance sheet
A39: Equity Weight (%) | B39: =B37/(B37+B38) -> 0.82374632 | J39: Equity / (Equity + Debt)
A40: Debt Weight (%) | B40: =B38/(B37+B38) -> 0.17625368 | J40: Debt / (Equity + Debt)
A42: Weighted Average Cost of Capital (%) | B42: =B31*B39+B35*B40 -> 0.105274 | J42: WACC = Ke*We + Kd(1-t)*Wd
A44: Terminal Value Assumptions
A45: Terminal Growth Rate (%) | B45: 0.025 | J45: Perpetuity growth — slightly above long-run inflation for tech company
A46: Exit EV/EBITDA Multiple (x) | B46: 18 | J46: Cross-check: peer median LTM EV/EBITDA = 17.9x (from comps model)

Sheet Unlevered Free Cash Flow
A1: Oracle Corporation (NYSE: ORCL)
A2: Unlevered Free Cash Flow Build
B4: FY2023A | C4: FY2024A | D4: FY2025A | E4: FY2026E | F4: FY2027E | G4: FY2028E | H4: FY2029E | I4: FY2030E
A6: Revenue
A7: Total Revenue ($mm) | B7: =Assumptions!B8 -> 49954 | C7: =Assumptions!C8 -> 52961 | D7: =Assumptions!D8 -> 57399 | E7: =Assumptions!E8 -> 68300 | F7: =Assumptions!F8 -> 88400 | G7: =Assumptions!G8 -> 106100 | H7: =Assumptions!H8 -> 122000 | I7: =Assumptions!I8 -> 136600
A8: Revenue Growth (%) | C8: =Assumptions!C9 -> 0.06019538 | D8: =Assumptions!D9 -> 0.083797511 | E8: =Assumptions!E9 -> 0.1899162 | F8: =Assumptions!F9 -> 0.2942899 | G8: =Assumptions!G9 -> 0.20022624 | H8: =Assumptions!H9 -> 0.14985862 | I8: =Assumptions!I9 -> 0.11967213
A10: Net Operating Profit After Tax (NOPAT)
A11: EBIT (Operating Income) ($mm) | B11: =Assumptions!B16 -> 13059.35 | C11: =Assumptions!C16 -> 15370.797 | D11: =Assumptions!D16 -> 17675.284 | E11: =Assumptions!E16 -> 19686 | F11: =Assumptions!F16 -> 25012 | G11: =Assumptions!G16 -> 30684 | H11: =Assumptions!H16 -> 36900 | I11: =Assumptions!I16 -> 41970
A12: Less: Taxes on EBIT ($mm) | B12: =-B11*B13 -> -1958.9025 | C12: =-C11*C13 -> -2290.2488 | D12: =-D11*D13 -> -2403.8387 | E12: =-E11*E13 -> -3740.34 | F12: =-F11*F13 -> -4752.28 | G12: =-G11*G13 -> -5829.96 | H12: =-H11*H13 -> -7011 | I12: =-I11*I13 -> -7974.3
A13: Effective Tax Rate (%) | B13: =Assumptions!B24 -> 0.15 | C13: =Assumptions!C24 -> 0.149 | D13: =Assumptions!D24 -> 0.136 | E13: =Assumptions!E24 -> 0.19 | F13: =Assumptions!F24 -> 0.19 | G13: =Assumptions!G24 -> 0.19 | H13: =Assumptions!H24 -> 0.19 | I13: =Assumptions!I24 -> 0.19
A14: NOPAT ($mm) | B14: =B11+B12 -> 11100.447 | C14: =C11+C12 -> 13080.548 | D14: =D11+D12 -> 15271.446 | E14: =E11+E12 -> 15945.66 | F14: =F11+F12 -> 20259.72 | G14: =G11+G12 -> 24854.04 | H14: =H11+H12 -> 29889 | I14: =I11+I12 -> 33995.7
A16: Adjustments to Unlevered Free Cash Flow
A17: Plus: Depreciation & Amortization ($mm) | B17: =Assumptions!B14 -> 6108 | C17: =Assumptions!C14 -> 6089 | D17: =Assumptions!D14 -> 6174 | E17: =Assumptions!E14 -> 9000 | F17: =Assumptions!F14 -> 13000 | G17: =Assumptions!G14 -> 16000 | H17: =Assumptions!H14 -> 18000 | I17: =Assumptions!I14 -> 19500
A18: Less: Capital Expenditures ($mm) | B18: =-Assumptions!B20 -> -8695 | C18: =-Assumptions!C20 -> -6866 | D18: =-Assumptions!D20 -> -21194 | E18: =-Assumptions!E20 -> -42000 | F18: =-Assumptions!F20 -> -38000 | G18: =-Assumptions!G20 -> -30000 | H18: =-Assumptions!H20 -> -25000 | I18: =-Assumptions!I20 -> -22000
A19: Less: Change in Net Working Capital ($mm) | B19: =-Assumptions!B22 -> -800 | C19: =-Assumptions!C22 -> -600 | D19: =-Assumptions!D22 -> -700 | E19: =-Assumptions!E22 -> -163 | F19: =-Assumptions!F22 -> -302 | G19: =-Assumptions!G22 -> -266 | H19: =-Assumptions!H22 -> -239 | I19: =-Assumptions!I22 -> -219
A21: Unlevered Free Cash Flow ($mm) | B21: =B14+B17+B18+B19 -> 7713.4473 | C21: =C14+C17+C18+C19 -> 11703.548 | D21: =D14+D17+D18+D19 -> -448.55419 | E21: =E14+E17+E18+E19 -> -17217.34 | F21: =F14+F17+F18+F19 -> -5042.28 | G21: =G14+G17+G18+G19 -> 10588.04 | H21: =H14+H17+H18+H19 -> 22650 | I21: =I14+I17+I18+I19 -> 31276.7
A23: Memo: Cash Flow Conversion Metrics
A24: UFCF Margin (%) | B24: =IF(B7=0,0,B21/B7) -> 0.154411 | C24: =IF(C7=0,0,C21/C7) -> 0.22098428 | D24: =IF(D7=0,0,D21/D7) -> -0.0078146691 | E24: =IF(E7=0,0,E21/E7) -> -0.25208404 | F24: =IF(F7=0,0,F21/F7) -> -0.057039367 | G24: =IF(G7=0,0,G21/G7) -> 0.099793025 | H24: =IF(H7=0,0,H21/H7) -> 0.18565574 | I24: =IF(I7=0,0,I21/I7) -> 0.22896559
A25: UFCF Growth (%) | C25: =IF(B21=0,0,C21/B21-1) -> 0.51729155 | D25: =IF(C21=0,0,D21/C21-1) -> -1.0383263 | E25: =IF(D21=0,0,E21/D21-1) -> 37.38408 | F25: =IF(E21=0,0,F21/E21-1) -> -0.70713943 | G25: =IF(F21=0,0,G21/F21-1) -> -3.0998517 | H25: =IF(G21=0,0,H21/G21-1) -> 1.1392061 | I25: =IF(H21=0,0,I21/H21-1) -> 0.38086976
A26: CapEx as % of Revenue | B26: =Assumptions!B21 -> 0.17406014 | C26: =Assumptions!C21 -> 0.12964257 | D26: =Assumptions!D21 -> 0.36923988 | E26: =Assumptions!E21 -> 0.61493411 | F26: =Assumptions!F21 -> 0.42986425 | G26: =Assumptions!G21 -> 0.28275212 | H26: =Assumptions!H21 -> 0.20491803 | I26: =Assumptions!I21 -> 0.16105417
A27: D&A as % of Revenue | B27: =Assumptions!B15 -> 0.12227249 | C27: =Assumptions!C15 -> 0.11497139 | D27: =Assumptions!D15 -> 0.10756285 | E27: =Assumptions!E15 -> 0.1317716 | F27: =Assumptions!F15 -> 0.14705882 | G27: =Assumptions!G15 -> 0.15080113 | H27: =Assumptions!H15 -> 0.14754098 | I27: =Assumptions!I15 -> 0.14275256
A28: EBITDA Margin (%) | B28: =Assumptions!B13 -> 0.3837 | C28: =Assumptions!C13 -> 0.4052 | D28: =Assumptions!D13 -> 0.4155 | E28: =Assumptions!E13 -> 0.42 | F28: =Assumptions!F13 -> 0.43 | G28: =Assumptions!G13 -> 0.44 | H28: =Assumptions!H13 -> 0.45 | I28: =Assumptions!I13 -> 0.45

Sheet DCF Valuation
A1: Oracle Corporation (NYSE: ORCL)
A2: Discounted Cash Flow Valuation
A4: Stage 1: Present Value of Explicit Forecast Period Cash Flows
B5: FY2026E | C5: FY2027E | D5: FY2028E | E5: FY2029E | F5: FY2030E
A7: Unlevered Free Cash Flow ($mm) | B7: ='Unlevered Free Cash Flow'!E21 -> -17217.34 | C7: ='Unlevered Free Cash Flow'!F21 -> -5042.28 | D7: ='Unlevered Free Cash Flow'!G21 -> 10588.04 | E7: ='Unlevered Free Cash Flow'!H21 -> 22650 | F7: ='Unlevered Free Cash Flow'!I21 -> 31276.7
A8: Discount Period (mid-year convention) | B8: 0.5 | C8: 1.5 | D8: 2.5 | E8: 3.5 | F8: 4.5
A9: Discount Factor | B9: =1/(1+Assumptions!$B$42)^B8 -> 0.95118506 | C9: =1/(1+Assumptions!$B$42)^C8 -> 0.86058756 | D9: =1/(1+Assumptions!$B$42)^D8 -> 0.7786192 | E9: =1/(1+Assumptions!$B$42)^E8 -> 0.70445808 | F9: =1/(1+Assumptions!$B$42)^F8 -> 0.63736058
A10: Present Value of Free Cash Flow ($mm) | B10: =B7*B9 -> -16376.877 | C10: =C7*C9 -> -4339.3235 | D10: =D7*D9 -> 8244.0513 | E10: =E7*E9 -> 15955.975 | F10: =F7*F9 -> 19934.536
A12: Sum of Present Values — Stage 1 ($mm) | B12: =SUM(B10:F10) -> 23418.362
A14: Stage 2: Terminal Value
A16: Method 1: Perpetuity Growth Method
A17: Terminal Year UFCF ($mm) | B17: =F7 -> 31276.7
A18: Terminal Growth Rate (%) | B18: =Assumptions!B45 -> 0.025
A19: WACC (%) | B19: =Assumptions!B42 -> 0.105274
A20: Terminal Value ($mm) | B20: =B17*(1+B18)/(B19-B18) -> 399364.87
A21: PV of Terminal Value ($mm) | B21: =B20/(1+B19)^4.5 -> 254539.42
A23: Method 2: Exit Multiple Method
A24: Terminal Year EBITDA ($mm) | B24: =Assumptions!I12 -> 61470
A25: Exit EV/EBITDA Multiple (x) | B25: =Assumptions!B46 -> 18
A26: Terminal Value ($mm) | B26: =B24*B25 -> 1106460
A27: PV of Terminal Value ($mm) | B27: =B26/(1+B19)^4.5 -> 705213.99
A29: Enterprise Value to Equity Value Bridge
B30: Perpetuity Growth | C30: Exit Multiple
A31: Sum PV — Stage 1 ($mm) | B31: =$B$12 -> 23418.362 | C31: =$B$12 -> 23418.362
A32: Plus: PV of Terminal Value ($mm) | B32: =B21 -> 254539.42 | C32: =B27 -> 705213.99
A33: Enterprise Value ($mm) | B33: =B31+B32 -> 277957.79 | C33: =C31+C32 -> 728632.35
A35: Less: Total Debt ($mm) | B35: =Assumptions!B38 -> 95502 | C35: =Assumptions!B38 -> 95502
A36: Less: Minority Interest ($mm) | B36: 518 | C36: 518
A37: Plus: Cash & Equivalents ($mm) | B37: 10456 | C37: 10456
A39: Equity Value ($mm) | B39: =B33-B35-B36+B37 -> 192393.79 | C39: =C33-C35-C36+C37 -> 643068.35
A41: Diluted Shares Outstanding (mm) | B41: 2870 | C41: 2870
A42: Implied Share Price ($) | B42: =IF(B41=0,"",B39/B41) -> 67.036163 | C42: =IF(C41=0,"",C39/C41) -> 224.06563
A44: Current Share Price ($) | B44: 155.52 | C44: 155.52
A45: Implied Upside / (Downside) (%) | B45: =IF(B44=0,"",B42/B44-1) -> -0.56895472 | C45: =IF(C44=0,"",C42/C44-1) -> 0.4407512
A47: Terminal Value as % of Enterprise Value | B47: =IF(B33=0,"",B32/B33) -> 0.91574849 | C47: =IF(C33=0,"",C32/C33) -> 0.96785984
A48: Implied Terminal EV/EBITDA (Perp. Growth) | B48: =IF(B24=0,"",B20/B24) -> 6.4969069
A50: Sensitivity Analysis: Implied Share Price ($)
A52: Perpetuity Growth — WACC vs. Terminal Growth Rate
A53: WACC \ Growth | B53: 1.5% | C53: 2.0% | D53: 2.5% | E53: 3.0% | F53: 3.5%
A54: 0.09 | B54: =($B$12+('Unlevered Free Cash Flow'!$I$21*(1+B$63)/($A54-B$63))/(1+$A54)^4.5-$B$35-$B$36+$B$37)/$B$41 -> 78.42123 | C54: =($B$12+('Unlevered Free Cash Flow'!$I$21*(1+C$63)/($A54-C$63))/(1+$A54)^4.5-$B$35-$B$36+$B$37)/$B$41 -> 86.097619 | D54: =($B$12+('Unlevered Free Cash Flow'!$I$21*(1+D$63)/($A54-D$63))/(1+$A54)^4.5-$B$35-$B$36+$B$37)/$B$41 -> 94.954991 | E54: =($B$12+('Unlevered Free Cash Flow'!$I$21*(1+E$63)/($A54-E$63))/(1+$A54)^4.5-$B$35-$B$36+$B$37)/$B$41 -> 105.28859 | F54: =($B$12+('Unlevered Free Cash Flow'!$I$21*(1+F$63)/($A54-F$63))/(1+$A54)^4.5-$B$35-$B$36+$B$37)/$B$41 -> 117.50103
...

Sheet Valuation Summary
A1: Oracle Corporation (NYSE: ORCL)
A2: Valuation Summary — Football Field
A3: Market data as of March 19, 2026 | Current price: $155.52
A5: Discounted Cash Flow Scenario Analysis
A6: Scenario Parameter | B6: Bear Case | C6: Base Case | D6: Bull Case
A7: Levered Beta | B7: 1.65 | C7: 1.4 | D7: 1.2
A8: Cost of Equity (%) | B8: 0.13375 | C8: 0.12 | D8: 0.109
A9: Weighted Average Cost of Capital (%) | B9: 0.11659601 | C9: 0.10527014 | D9: 0.096209435
A10: Terminal Growth Rate (%) | B10: 0.02 | C10: 0.025 | D10: 0.03
A11: Exit EV/EBITDA Multiple (x) | B11: 16 | C11: 18 | D11: 20
A13: Implied Share Price | B13: Bear Case | C13: Base Case | D13: Bull Case
A14: DCF — Perpetuity Growth Method ($) | B14: 47.876355 | C14: 67.042021 | D14: 90.9222
A15: DCF — Exit Multiple Method ($) | B15: 186.44624 | C15: 224.06968 | D15: 262.11727
A16: Average of Both Methods ($) | B16: 117.1613 | C16: 145.55585 | D16: 176.51973
A18: Comparable Companies Implied Valuation
A19: Methodology | B19: Low (25th Pctl) | C19: Median | D19: High (75th Pctl) | E19: Mean | F19: Oracle Metric
A20: LTM EV / Revenue | B20: 59.185209 | C20: 72.184983 | D20: 156.18352 | E20: 94.784589 | F20: $57.4B
A21: LTM EV / EBITDA | B21: 87.784599 | C21: 116.8724 | D21: 182.1122 | E21: 146.62507 | F21: $23.9B
A22: NTM EV / Revenue | B22: 66.568293 | C22: 91.556098 | D22: 157.00035 | E22: 101.07526 | F22: $68.3B
A23: NTM EV / EBITDA (est.) | B23: 80.438309 | C23: 137.29449 | D23: 220.35395 | E23: 148.66573 | F23: $28.4B
A24: Comps Implied Range (LTM EV/EBITDA) | B24: =B21 -> 87.784599 | C24: =C21 -> 116.8724 | D24: =D21 -> 182.1122
A26: Market Reference Points
A27: 52-Week Trading Range | B27: 118.86 | C27: =(B27+D27)/2 -> 232.29 | D27: 345.72
A28: Analyst Consensus Target Price (12-month) | B28: 155 | C28: 228.5 | D28: 400
A30: Consolidated Football Field
A31: Methodology | B31: Low ($) | C31: Base ($) | D31: High ($) | E31: Weight | F31: Notes
A32: DCF — Perpetuity Growth | B32: 47.876355 | C32: 67.042021 | D32: 90.9222 | E32: 0.15 | F32: Bear/Base/Bull — forward beta assumption
A33: DCF — Exit Multiple | B33: 186.44624 | C33: 224.06968 | D33: 262.11727 | E33: 0.35 | F33: Bear/Base/Bull — primary DCF method
A34: Comps — LTM EV/EBITDA | B34: =B21 -> 87.784599 | C34: =C21 -> 116.8724 | D34: =D21 -> 182.1122 | E34: 0.25 | F34: Peer 25th/Median/75th percentile
A35: Comps — NTM EV/EBITDA | B35: =B23 -> 80.438309 | C35: =C23 -> 137.29449 | D35: =D23 -> 220.35395 | E35: 0.1 | F35: Forward estimate; less reliable
A36: 52-Week Trading Range | B36: =B27 -> 118.86 | C36: =C27 -> 232.29 | D36: =D27 -> 345.72 | E36: 0.1 | F36: $118.86 low to $345.72 high
A37: Analyst Consensus | B37: =B28 -> 155 | C37: =C28 -> 228.5 | D37: =D28 -> 400 | E37: 0.05 | F37: 54 analysts; Buy consensus; median $228.50
A38: Weighted Average Implied Share Price | B38: =SUMPRODUCT(B32:B37,$E$32:$E$37) -> 122.06362 | C38: =SUMPRODUCT(C32:C37,$E$32:$E$37) -> 166.08224 | D38: =SUMPRODUCT(D32:D37,$E$32:$E$37) -> 227.51482 | E38: =SUM(E32:E37) -> 1
A40: Current Share Price ($) | B40: 155.52
A41: Implied Upside / (Downside) — Low (%) | B41: =B38/B40-1 -> -0.21512592
A42: Implied Upside / (Downside) — Base (%) | B42: =C38/B40-1 -> 0.067915651
A43: Implied Upside / (Downside) — High (%) | B43: =D38/B40-1 -> 0.46292965
A45: Recommendation
A46: Target Price (12-Month, Base Case) | B46: =C38 -> 166.08224
A47: Rating | B47: BUY
...
